Workbook

Sheet Objectives
C1: LGD is a lifetime concept. Once defaulted, need to track the recoveries for lifetime.
B4: Objective | C4: Model a lifetime recoveries for Secured and Unsecured loans

Sheet MEF
D1: =AVERAGE(D3:D80) -> 0.069586248
B2: observation_date | C2: Performance | D2: Annual DR
B3: 37895 | C3: 37987 | D3: 0.0508174
B4: 37987 | C4: 38078 | D4: 0.04632656
B5: 38078 | C5: 38169 | D5: 0.04396296
B6: 38169 | C6: 38261 | D6: 0.04112664
B7: 38261 | C7: 38353 | D7: 0.03876304
B8: 38353 | C8: 38443 | D8: 0.0378176
B9: 38443 | C9: 38534 | D9: 0.03710852
B10: 38534 | C10: 38626 | D10: 0.03687216
B11: 38626 | C11: 38718 | D11: 0.03639944
B12: 38718 | C12: 38808 | D12: 0.03569036
B13: 38808 | C13: 38899 | D13: 0.03569036
B14: 38899 | C14: 38991 | D14: 0.03734488
... B80: 44927 | C80: 45017 | D80: 0.033009709
B81: 45017

Sheet LGD_Chain Ladder
B2: Step1: Data Preparation
B3: Identify the active and closed accounts that have gone 90DPD
B4: and have not been restructured. These are the accounts that will be used in the analysis.
B6: Step2: Outstanding Amount
B7: For each year of default from (2013 to 2022 – here), obtain the outstanding amount for the accounts defaulted in that
B8: year and the year wise Recoveries made against this amount outstanding for crystalization period of 5 years
B10: Year of Default | C10: Amount Outstanding | D10: 1 | E10: 2 | F10: 3 | G10: 4 | H10: 5
B11: 2013 | C11: 18301225 | D11: 3239503.2 | E11: 1278265.6 | F11: 953213.2 | G11: 671317.13 | H11: 798359.89
B12: 2014 | C12: 16347920 | D12: 2426505 | E12: 1392415.9 | F12: 1075402.2 | G12: 683108.67 | H12: 883278.21
B13: 2015 | C13: 20815172 | D13: 3637371.7 | E13: 1957848.1 | F13: 1342600.9 | G13: 856133.18 | H13: 882339.66
B14: 2016 | C14: 39677370 | D14: 7820326.9 | E14: 3247143.1 | F14: 2043404.6 | G14: 2283995 | H14: 2624758.5
B15: 2017 | C15: 86078298 | D15: 13151717 | E15: 10614294 | F15: 8122900.7 | G15: 4480967.7 | H15: 3206471.9
B16: 2018 | C16: 1.2687246e+08 | D16: 13022534 | E16: 14364742 | F16: 9593502.6 | G16: 2811549 | H16: 580320.74
B17: 2019 | C17: 1.5303796e+08 | D17: 18598106 | E17: 12187197 | F17: 10208054 | G17: 1194097.8
B18: 2020 | C18: 2.1034608e+08 | D18: 17983767 | E18: 9999855.7 | F18: 2071706.6
B19: 2021 | C19: 2.2803177e+08 | D19: 48750580 | E19: 6959192.4
B20: 2022 | C20: 35155453 | D20: 9947739.1
B22: Step 3: Present Value of Recoveries
B23: Obtain the present value of the recoveries made in subsequent years to the year of default. In the PV formula below,
B24: the interest rate used is 10%, where 𝑌𝐷 is the year of default and 𝑦 is the year of recovery.
B27: Year of Default | C27: Amount Outstanding | D27: 1 | E27: 2 | F27: 3 | G27: 4 | H27: 5
B28: 2013 | C28: 18301225 | D28: =D11/(1+10%)^$D$10 -> 2945002.9 | E28: =E11/(1+10%)^$E$10 -> 1056417.8 | F28: =F11/(1+10%)^$F$10 -> 716163.19 | G28: =G11/(1+10%)^$G$10 -> 458518.63 | H28: =H11/(1+10%)^$H$10 -> 495718.68
B29: 2014 | C29: 16347920 | D29: =D12/(1+10%)^$D$10 -> 2205913.6 | E29: =E12/(1+10%)^$E$10 -> 1150756.9 | F29: =F12/(1+10%)^$F$10 -> 807965.57 | G29: =G12/(1+10%)^$G$10 -> 466572.41 | H29: =H12/(1+10%)^$H$10 -> 548446.27
B30: 2015 | C30: 20815172 | D30: =D13/(1+10%)^$D$10 -> 3306701.6 | E30: =E13/(1+10%)^$E$10 -> 1618056.3 | F30: =F13/(1+10%)^$F$10 -> 1008715.9 | G30: =G13/(1+10%)^$G$10 -> 584750.48 | H30: =H13/(1+10%)^$H$10 -> 547863.51
B31: 2016 | C31: 39677370 | D31: =D14/(1+10%)^$D$10 -> 7109388.1 | E31: =E14/(1+10%)^$E$10 -> 2683589.4 | F31: =F14/(1+10%)^$F$10 -> 1535240.1 | G31: =G14/(1+10%)^$G$10 -> 1559999.4 | H31: =H14/(1+10%)^$H$10 -> 1629768.5
B32: 2017 | C32: 86078298 | D32: =D15/(1+10%)^$D$10 -> 11956107 | E32: =E15/(1+10%)^$E$10 -> 8772144.1 | F32: =F15/(1+10%)^$F$10 -> 6102855.5 | G32: =G15/(1+10%)^$G$10 -> 3060561.2 | H32: =H15/(1+10%)^$H$10 -> 1990966.8
B33: 2018 | C33: 1.2687246e+08 | D33: =D16/(1+10%)^$D$10 -> 11838667 | E33: =E16/(1+10%)^$E$10 -> 11871688 | F33: =F16/(1+10%)^$F$10 -> 7207740.5 | G33: =G16/(1+10%)^$G$10 -> 1920325.8 | H33: =H16/(1+10%)^$H$10 -> 360333.52
B34: 2019 | C34: 1.5303796e+08 | D34: =D17/(1+10%)^$D$10 -> 16907369 | E34: =E17/(1+10%)^$E$10 -> 10072064 | F34: =F17/(1+10%)^$F$10 -> 7669462 | G34: =G17/(1+10%)^$G$10 -> 815584.84
B35: 2020 | C35: 2.1034608e+08 | D35: =D18/(1+10%)^$D$10 -> 16348879 | E35: =E18/(1+10%)^$E$10 -> 8264343.5 | F35: =F18/(1+10%)^$F$10 -> 1556503.8
B36: 2021 | C36: 2.2803177e+08 | D36: =D19/(1+10%)^$D$10 -> 44318709 | E36: =E19/(1+10%)^$E$10 -> 5751398.7
B37: 2022 | C37: 35155453 | D37: =D20/(1+10%)^$D$10 -> 9043399.2
B39: Step 4: Estimation of Cumulative Recoveries
B40: Calculate the cumulatives recoveries against the year of default (𝑌𝐷) and conduct recovery analysis
B41: to ascertain the recovery pattern/trend.
B43: Year of Default | C43: Amount Outstanding | D43: 1 | E43: 2 | F43: 3 | G43: 4 | H43: 5
B44: 2013 | C44: 18301225 | D44: =D28 -> 2945002.9 | E44: =D44+E28 -> 4001420.7 | F44: =E44+F28 -> 4717583.9 | G44: =F44+G28 -> 5176102.6 | H44: =G44+H28 -> 5671821.2
B45: 2014 | C45: 16347920 | D45: =D29 -> 2205913.6 | E45: =D45+E29 -> 3356670.6 | F45: =E45+F29 -> 4164636.1 | G45: =F45+G29 -> 4631208.5 | H45: =G45+H29 -> 5179654.8
B46: 2015 | C46: 20815172 | D46: =D30 -> 3306701.6 | E46: =D46+E30 -> 4924757.9 | F46: =E46+F30 -> 5933473.8 | G46: =F46+G30 -> 6518224.3 | H46: =G46+H30 -> 7066087.8
B47: 2016 | C47: 39677370 | D47: =D31 -> 7109388.1 | E47: =D47+E31 -> 9792977.4 | F47: =E47+F31 -> 11328218 | G47: =F47+G31 -> 12888217 | H47: =G47+H31 -> 14517985
B48: 2017 | C48: 86078298 | D48: =D32 -> 11956107 | E48: =D48+E32 -> 20728251 | F48: =E48+F32 -> 26831106 | G48: =F48+G32 -> 29891667 | H48: =G48+H32 -> 31882634
...

Sheet Frye-Jacobs
B1: This spreadsheet illustrates the LGD function Frye-jacobs
B2: PD and LGD are correlated directly
C4: TTC PD | D4: 0.02 | F4: Corrlation betw PD and Expected Loss | J4: 0.1
C5: ELGD | D5: 0.25
B7: k | C7: =(NORMSINV(D4)-NORMSINV(D4*D5))/SQRT(1-J4) -> 0.55032105 | D7: PD | E7: LGD
D8: 0.0001 | E8: 0.098027194
D9: 0.00012 | E9: 0.10043664
D10: 0.000144 | E10: 0.10293136
D11: 0.0001728 | E11: 0.10551556
D12: 0.00020736 | E12: 0.10819377
D13: 0.000248832 | E13: 0.11097081
D14: 0.0002985984 | E14: 0.11385182
D15: 0.00035831808 | E15: 0.11684234
D16: 0.0004299817 | E16: 0.11994828
D17: 0.00051597804 | E17: 0.12317599
D18: 0.00061917364 | E18: 0.1265323
D19: 0.00074300837 | E19: 0.13002457
... D46: 0.10347264 | E46: 0.33794005
D47: 0.02 | F47: 0
D48: 0.02 | F48: 0.23030987
D50: 0 | G50: 0.23030987
D51: 0.02 | G51: 0.23030987

Sheet LGD Unsecured
E2: PIT LGD Model (Frye-Jacobs)
C4: Rho | D4: 0.1
A7: Retail Portfolio
H8: Forward Looking PIT PD Term Structure (built in PD Retail Portfolio sheet)
B9: Rating | C9: TTC PD | D9: E-LGD | E9: K | G9: Quarters | H9: 1 | I9: 2 | J9: 3 | K9: 4 | L9: 5 | M9: 6 | N9: 7 | O9: 8 | P9: 9 | Q9: 10 | R9: 11 | S9: 12 | T9: 13 | U9: 14 | V9: 15 | W9: 16 | X9: 17 | Y9: 18 | Z9: 19 | AA9: 20 | AB9: 21 | AC9: 22 | AD9: 23 | AE9: 24 | AF9: 25 | AG9: 26 | AH9: 27 | AI9: 28 | AJ9: 29 | AK9: 30 | AL9: 31 | AM9: 32 | AN9: 33 | AO9: 34 | AP9: 35 | AQ9: 36
B10: 1 | C10: 7.5008439e-05 | D10: ='LGD_Chain Ladder'!$J$71 -> 0.68247911 | E10: =(NORMSINV(C10)-(NORMSINV(C10*D10)))/SQRT((1-$D$4)) -> 0.098907098 | H10: 7.2680096e-05 | I10: 7.3452771e-05 | J10: 7.1516812e-05 | K10: 7.3066555e-05 | L10: 7.1126916e-05 | M10: 7.0735525e-05 | N10: 7.0735525e-05 | O10: 7.1905472e-05 | P10: 6.9549676e-05 | Q10: 7.1905472e-05 | R10: 7.0342373e-05 | S10: 7.1516812e-05 | T10: 7.0342373e-05 | U10: 6.9947185e-05 | V10: 7.2680096e-05 | W10: 7.1516812e-05 | X10: 6.9947185e-05 | Y10: 7.3452771e-05 | Z10: 7.0735525e-05 | AA10: 7.3452771e-05 | AB10: 7.3452771e-05 | AC10: 7.3452771e-05 | AD10: 7.3452771e-05 | AE10: 7.3452771e-05 | AF10: 7.3452771e-05 | AG10: 7.3452771e-05 | AH10: 7.3452771e-05 | AI10: 7.3452771e-05 | AJ10: 7.3452771e-05 | AK10: 7.3452771e-05 | AL10: 7.3452771e-05 | AM10: 7.3452771e-05 | AN10: 7.3452771e-05 | AO10: 7.3452771e-05 | AP10: 7.3452771e-05 | AQ10: 7.3452771e-05
B11: 2 | C11: 7.5008439e-05 | D11: ='LGD_Chain Ladder'!$J$71 -> 0.68247911 | E11: =(NORMSINV(C11)-(NORMSINV(C11*D11)))/SQRT((1-$D$4)) -> 0.098907098 | H11: 7.2680096e-05 | I11: 7.3452771e-05 | J11: 7.1516812e-05 | K11: 7.3066555e-05 | L11: 7.1126916e-05 | M11: 7.0735525e-05 | N11: 7.0735525e-05 | O11: 7.1905472e-05 | P11: 6.9549676e-05 | Q11: 7.1905472e-05 | R11: 7.0342373e-05 | S11: 7.1516812e-05 | T11: 7.0342373e-05 | U11: 6.9947185e-05 | V11: 7.2680096e-05 | W11: 7.1516812e-05 | X11: 6.9947185e-05 | Y11: 7.3452771e-05 | Z11: 7.0735525e-05 | AA11: 7.3452771e-05 | AB11: 7.3452771e-05 | AC11: 7.3452771e-05 | AD11: 7.3452771e-05 | AE11: 7.3452771e-05 | AF11: 7.3452771e-05 | AG11: 7.3452771e-05 | AH11: 7.3452771e-05 | AI11: 7.3452771e-05 | AJ11: 7.3452771e-05 | AK11: 7.3452771e-05 | AL11: 7.3452771e-05 | AM11: 7.3452771e-05 | AN11: 7.3452771e-05 | AO11: 7.3452771e-05 | AP11: 7.3452771e-05 | AQ11: 7.3452771e-05
B12: 3 | C12: 7.5008439e-05 | D12: ='LGD_Chain Ladder'!$J$71 -> 0.68247911 | E12: =(NORMSINV(C12)-(NORMSINV(C12*D12)))/SQRT((1-$D$4)) -> 0.098907098 | H12: 7.2680096e-05 | I12: 7.3452771e-05 | J12: 7.1516812e-05 | K12: 7.3066555e-05 | L12: 7.1126916e-05 | M12: 7.0735525e-05 | N12: 7.0735525e-05 | O12: 7.1905472e-05 | P12: 6.9549676e-05 | Q12: 7.1905472e-05 | R12: 7.0342373e-05 | S12: 7.1516812e-05 | T12: 7.0342373e-05 | U12: 6.9947185e-05 | V12: 7.2680096e-05 | W12: 7.1516812e-05 | X12: 6.9947185e-05 | Y12: 7.3452771e-05 | Z12: 7.0735525e-05 | AA12: 7.3452771e-05 | AB12: 7.3452771e-05 | AC12: 7.3452771e-05 | AD12: 7.3452771e-05 | AE12: 7.3452771e-05 | AF12: 7.3452771e-05 | AG12: 7.3452771e-05 | AH12: 7.3452771e-05 | AI12: 7.3452771e-05 | AJ12: 7.3452771e-05 | AK12: 7.3452771e-05 | AL12: 7.3452771e-05 | AM12: 7.3452771e-05 | AN12: 7.3452771e-05 | AO12: 7.3452771e-05 | AP12: 7.3452771e-05 | AQ12: 7.3452771e-05
B13: 4 | C13: 7.5008439e-05 | D13: ='LGD_Chain Ladder'!$J$71 -> 0.68247911 | E13: =(NORMSINV(C13)-(NORMSINV(C13*D13)))/SQRT((1-$D$4)) -> 0.098907098 | H13: 7.2680096e-05 | I13: 7.3452771e-05 | J13: 7.1516812e-05 | K13: 7.3066555e-05 | L13: 7.1126916e-05 | M13: 7.0735525e-05 | N13: 7.0735525e-05 | O13: 7.1905472e-05 | P13: 6.9549676e-05 | Q13: 7.1905472e-05 | R13: 7.0342373e-05 | S13: 7.1516812e-05 | T13: 7.0342373e-05 | U13: 6.9947185e-05 | V13: 7.2680096e-05 | W13: 7.1516812e-05 | X13: 6.9947185e-05 | Y13: 7.3452771e-05 | Z13: 7.0735525e-05 | AA13: 7.3452771e-05 | AB13: 7.3452771e-05 | AC13: 7.3452771e-05 | AD13: 7.3452771e-05 | AE13: 7.3452771e-05 | AF13: 7.3452771e-05 | AG13: 7.3452771e-05 | AH13: 7.3452771e-05 | AI13: 7.3452771e-05 | AJ13: 7.3452771e-05 | AK13: 7.3452771e-05 | AL13: 7.3452771e-05 | AM13: 7.3452771e-05 | AN13: 7.3452771e-05 | AO13: 7.3452771e-05 | AP13: 7.3452771e-05 | AQ13: 7.3452771e-05
B14: 5 | C14: 7.5008439e-05 | D14: ='LGD_Chain Ladder'!$J$71 -> 0.68247911 | E14: =(NORMSINV(C14)-(NORMSINV(C14*D14)))/SQRT((1-$D$4)) -> 0.098907098 | H14: 7.2680096e-05 | I14: 7.3452771e-05 | J14: 7.1516812e-05 | K14: 7.3066555e-05 | L14: 7.1126916e-05 | M14: 7.0735525e-05 | N14: 7.0735525e-05 | O14: 7.1905472e-05 | P14: 6.9549676e-05 | Q14: 7.1905472e-05 | R14: 7.0342373e-05 | S14: 7.1516812e-05 | T14: 7.0342373e-05 | U14: 6.9947185e-05 | V14: 7.2680096e-05 | W14: 7.1516812e-05 | X14: 6.9947185e-05 | Y14: 7.3452771e-05 | Z14: 7.0735525e-05 | AA14: 7.3452771e-05 | AB14: 7.3452771e-05 | AC14: 7.3452771e-05 | AD14: 7.3452771e-05 | AE14: 7.3452771e-05 | AF14: 7.3452771e-05 | AG14: 7.3452771e-05 | AH14: 7.3452771e-05 | AI14: 7.3452771e-05 | AJ14: 7.3452771e-05 | AK14: 7.3452771e-05 | AL14: 7.3452771e-05 | AM14: 7.3452771e-05 | AN14: 7.3452771e-05 | AO14: 7.3452771e-05 | AP14: 7.3452771e-05 | AQ14: 7.3452771e-05
B15: 6 | C15: 7.5008439e-05 | D15: ='LGD_Chain Ladder'!$J$71 -> 0.68247911 | E15: =(NORMSINV(C15)-(NORMSINV(C15*D15)))/SQRT((1-$D$4)) -> 0.098907098 | H15: 7.2680096e-05 | I15: 7.3452771e-05 | J15: 7.1516812e-05 | K15: 7.3066555e-05 | L15: 7.1126916e-05 | M15: 7.0735525e-05 | N15: 7.0735525e-05 | O15: 7.1905472e-05 | P15: 6.9549676e-05 | Q15: 7.1905472e-05 | R15: 7.0342373e-05 | S15: 7.1516812e-05 | T15: 7.0342373e-05 | U15: 6.9947185e-05 | V15: 7.2680096e-05 | W15: 7.1516812e-05 | X15: 6.9947185e-05 | Y15: 7.3452771e-05 | Z15: 7.0735525e-05 | AA15: 7.3452771e-05 | AB15: 7.3452771e-05 | AC15: 7.3452771e-05 | AD15: 7.3452771e-05 | AE15: 7.3452771e-05 | AF15: 7.3452771e-05 | AG15: 7.3452771e-05 | AH15: 7.3452771e-05 | AI15: 7.3452771e-05 | AJ15: 7.3452771e-05 | AK15: 7.3452771e-05 | AL15: 7.3452771e-05 | AM15: 7.3452771e-05 | AN15: 7.3452771e-05 | AO15: 7.3452771e-05 | AP15: 7.3452771e-05 | AQ15: 7.3452771e-05
B16: 7 | C16: 0.00027779067 | D16: ='LGD_Chain Ladder'!$J$71 -> 0.68247911 | E16: =(NORMSINV(C16)-(NORMSINV(C16*D16)))/SQRT((1-$D$4)) -> 0.10725448 | H16: 0.0002691652 | I16: 0.0002720276 | J16: 0.00026485582 | K16: 0.00027059684 | L16: 0.00026341146 | M16: 0.00026196156 | N16: 0.00026196156 | O16: 0.0002662956 | P16: 0.00025756866 | Q16: 0.0002662956 | R16: 0.00026050515 | S16: 0.00026485582 | T16: 0.00026050515 | U16: 0.0002590412 | V16: 0.0002691652 | W16: 0.00026485582 | X16: 0.0002590412 | Y16: 0.0002720276 | Z16: 0.00026196156 | AA16: 0.0002720276 | AB16: 0.0002720276 | AC16: 0.0002720276 | AD16: 0.0002720276 | AE16: 0.0002720276 | AF16: 0.0002720276 | AG16: 0.0002720276 | AH16: 0.0002720276 | AI16: 0.0002720276 | AJ16: 0.0002720276 | AK16: 0.0002720276 | AL16: 0.0002720276 | AM16: 0.0002720276 | AN16: 0.0002720276 | AO16: 0.0002720276 | AP16: 0.0002720276 | AQ16: 0.0002720276
B17: 8 | C17: 0.00098863195 | D17: ='LGD_Chain Ladder'!$J$71 -> 0.68247911 | E17: =(NORMSINV(C17)-(NORMSINV(C17*D17)))/SQRT((1-$D$4)) -> 0.11766418 | H17: 0.00095790293 | I17: 0.00096810026 | J17: 0.00094255112 | K17: 0.00096300316 | L17: 0.00093740583 | M17: 0.00093224088 | N17: 0.00093224088 | O17: 0.00094768018 | P17: 0.00091659239 | Q17: 0.00094768018 | R17: 0.00092705276 | S17: 0.00094255112 | T17: 0.00092705276 | U17: 0.00092183784 | V17: 0.00095790293 | W17: 0.00094255112 | X17: 0.00092183784 | Y17: 0.00096810026 | Z17: 0.00093224088 | AA17: 0.00096810026 | AB17: 0.00096810026 | AC17: 0.00096810026 | AD17: 0.00096810026 | AE17: 0.00096810026 | AF17: 0.00096810026 | AG17: 0.00096810026 | AH17: 0.00096810026 | AI17: 0.00096810026 | AJ17: 0.00096810026 | AK17: 0.00096810026 | AL17: 0.00096810026 | AM17: 0.00096810026 | AN17: 0.00096810026 | AO17: 0.00096810026 | AP17: 0.00096810026 | AQ17: 0.00096810026
B18: 9 | C18: 0.0013459513 | D18: ='LGD_Chain Ladder'!$J$71 -> 0.68247911 | E18: =(NORMSINV(C18)-(NORMSINV(C18*D18)))/SQRT((1-$D$4)) -> 0.12066659 | H18: 0.0013040942 | I18: 0.0013179842 | J18: 0.0012831835 | K18: 0.0013110413 | L18: 0.0012761751 | M18: 0.0012691401 | N18: 0.0012691401 | O18: 0.0012901697 | P18: 0.0012478258 | Q18: 0.0012901697 | R18: 0.0012620735 | S18: 0.0012831835 | T18: 0.0012620735 | U18: 0.0012549704 | V18: 0.0013040942 | W18: 0.0012831835 | X18: 0.0012549704 | Y18: 0.0013179842 | Z18: 0.0012691401 | AA18: 0.0013179842 | AB18: 0.0013179842 | AC18: 0.0013179842 | AD18: 0.0013179842 | AE18: 0.0013179842 | AF18: 0.0013179842 | AG18: 0.0013179842 | AH18: 0.0013179842 | AI18: 0.0013179842 | AJ18: 0.0013179842 | AK18: 0.0013179842 | AL18: 0.0013179842 | AM18: 0.0013179842 | AN18: 0.0013179842 | AO18: 0.0013179842 | AP18: 0.0013179842 | AQ18: 0.0013179842
B19: 10 | C19: 0.0035720655 | D19: ='LGD_Chain Ladder'!$J$71 -> 0.68247911 | E19: =(NORMSINV(C19)-(NORMSINV(C19*D19)))/SQRT((1-$D$4)) -> 0.13184799 | H19: 0.0034606179 | I19: 0.0034975984 | J19: 0.0034049503 | K19: 0.0034791135 | L19: 0.0033862944 | M19: 0.0033675679 | N19: 0.0033675679 | O19: 0.0034235482 | P19: 0.0033108361 | Q19: 0.0034235482 | R19: 0.0033487582 | S19: 0.0034049503 | T19: 0.0033487582 | U19: 0.0033298521 | V19: 0.0034606179 | W19: 0.0034049503 | X19: 0.0033298521 | Y19: 0.0034975984 | Z19: 0.0033675679 | AA19: 0.0034975984 | AB19: 0.0034975984 | AC19: 0.0034975984 | AD19: 0.0034975984 | AE19: 0.0034975984 | AF19: 0.0034975984 | AG19: 0.0034975984 | AH19: 0.0034975984 | AI19: 0.0034975984 | AJ19: 0.0034975984 | AK19: 0.0034975984 | AL19: 0.0034975984 | AM19: 0.0034975984 | AN19: 0.0034975984 | AO19: 0.0034975984 | AP19: 0.0034975984 | AQ19: 0.0034975984
B20: 11 | C20: 0.0078750113 | D20: ='LGD_Chain Ladder'!$J$71 -> 0.68247911 | E20: =(NORMSINV(C20)-(NORMSINV(C20*D20)))/SQRT((1-$D$4)) -> 0.14345704 | H20: 0.0076277559 | I20: 0.0077097889 | J20: 0.0075042911 | K20: 0.0076687827 | L20: 0.0074629198 | M20: 0.007421395 | N20: 0.007421395 | O20: 0.0075455363 | P20: 0.0072956134 | Q20: 0.0075455363 | R20: 0.0073796886 | S20: 0.0075042911 | T20: 0.0073796886 | U20: 0.0073377714 | V20: 0.0076277559 | W20: 0.0075042911 | X20: 0.0073377714 | Y20: 0.0077097889 | Z20: 0.007421395 | AA20: 0.0077097889 | AB20: 0.0077097889 | AC20: 0.0077097889 | AD20: 0.0077097889 | AE20: 0.0077097889 | AF20: 0.0077097889 | AG20: 0.0077097889 | AH20: 0.0077097889 | AI20: 0.0077097889 | AJ20: 0.0077097889 | AK20: 0.0077097889 | AL20: 0.0077097889 | AM20: 0.0077097889 | AN20: 0.0077097889 | AO20: 0.0077097889 | AP20: 0.0077097889 | AQ20: 0.0077097889
B21: 12 | C21: 0.01515043 | D21: ='LGD_Chain Ladder'!$J$71 -> 0.68247911 | E21: =(NORMSINV(C21)-(NORMSINV(C21*D21)))/SQRT((1-$D$4)) -> 0.15563303 | H21: 0.014669585 | I21: 0.014829079 | J21: 0.014429608 | K21: 0.014749347 | L21: 0.014349215 | M21: 0.014268533 | N21: 0.014268533 | O21: 0.014509767 | P21: 0.014024199 | Q21: 0.014509767 | R21: 0.014187507 | S21: 0.014429608 | T21: 0.014187507 | U21: 0.014106082 | V21: 0.014669585 | W21: 0.014429608 | X21: 0.014106082 | Y21: 0.014829079 | Z21: 0.014268533 | AA21: 0.014829079 | AB21: 0.014829079 | AC21: 0.014829079 | AD21: 0.014829079 | AE21: 0.014829079 | AF21: 0.014829079 | AG21: 0.014829079 | AH21: 0.014829079 | AI21: 0.014829079 | AJ21: 0.014829079 | AK21: 0.014829079 | AL21: 0.014829079 | AM21: 0.014829079 | AN21: 0.014829079 | AO21: 0.014829079 | AP21: 0.014829079 | AQ21: 0.014829079
... B26: 17 | C26: 0.32965791 | D26: ='LGD_Chain Ladder'!$J$71 -> 0.68247911 | E26: =(NORMSINV(C26)-(NORMSINV(C26*D26)))/SQRT((1-$D$4)) -> 0.33162624 | H26: 0.309983 | I26: 0.31632517 | J26: 0.30075238 | K26: 0.31313312 | L26: 0.29773882 | M26: 0.29475222 | N26: 0.29475222 | O26: 0.30379566 | P26: 0.28592765 | Q26: 0.30379566 | R26: 0.2917899 | S26: 0.30075238 | T26: 0.2917899 | U26: 0.28884924 | V26: 0.309983 | W26: 0.30075238 | X26: 0.28884924 | Y26: 0.31632517 | Z26: 0.29475222 | AA26: 0.31632517 | AB26: 0.31632517 | AC26: 0.31632517 | AD26: 0.31632517 | AE26: 0.31632517 | AF26: 0.31632517 | AG26: 0.31632517 | AH26: 0.31632517 | AI26: 0.31632517 | AJ26: 0.31632517 | AK26: 0.31632517 | AL26: 0.31632517 | AM26: 0.31632517 | AN26: 0.31632517 | AO26: 0.31632517 | AP26: 0.31632517 | AQ26: 0.31632517
E28: Final Result
E30: Retail Model | H30: Forward Looking LGDs
F31: Final PIT LGD | H31: Quarters
H32: 1 | I32: 2 | J32: 3 | K32: 4 | L32: 5 | M32: 6 | N32: 7 | O32: 8 | P32: 9 | Q32: 10 | R32: 11 | S32: 12 | T32: 13 | U32: 14 | V32: 15 | W32: 16 | X32: 17 | Y32: 18 | Z32: 19 | AA32: 20 | AB32: 21 | AC32: 22 | AD32: 23 | AE32: 24 | AF32: 25 | AG32: 26 | AH32: 27 | AI32: 28 | AJ32: 29 | AK32: 30 | AL32: 31 | AM32: 32 | AN32: 33 | AO32: 34 | AP32: 35 | AQ32: 36
F33: Rating | G33: 1 | H33: =NORMSDIST(NORMSINV(H10)-$E$10)/H10 -> 0.6678698 | I33: =NORMSDIST(NORMSINV(I10)-$E$10)/I10 -> 0.66803445 | J33: =NORMSDIST(NORMSINV(J10)-$E$10)/J10 -> 0.66761883 | K33: =NORMSDIST(NORMSINV(K10)-$E$10)/K10 -> 0.66795235 | L33: =NORMSDIST(NORMSINV(L10)-$E$10)/L10 -> 0.66753387 | M33: =NORMSDIST(NORMSINV(M10)-$E$10)/M10 -> 0.66744816 | N33: =NORMSDIST(NORMSINV(N10)-$E$10)/N10 -> 0.66744816 | O33: =NORMSDIST(NORMSINV(O10)-$E$10)/O10 -> 0.6677031 | ... AQ33: =NORMSDIST(NORMSINV(AQ10)-$E$10)/AQ10 -> 0.66803445
G34: 2 | H34: =NORMSDIST(NORMSINV(H11)-$E$11)/H11 -> 0.6678698 | I34: =NORMSDIST(NORMSINV(I11)-$E$11)/I11 -> 0.66803445 | J34: =NORMSDIST(NORMSINV(J11)-$E$11)/J11 -> 0.66761883 | K34: =NORMSDIST(NORMSINV(K11)-$E$11)/K11 -> 0.66795235 | L34: =NORMSDIST(NORMSINV(L11)-$E$11)/L11 -> 0.66753387 | M34: =NORMSDIST(NORMSINV(M11)-$E$11)/M11 -> 0.66744816 | N34: =NORMSDIST(NORMSINV(N11)-$E$11)/N11 -> 0.66744816 | O34: =NORMSDIST(NORMSINV(O11)-$E$11)/O11 -> 0.6677031 | ... AQ34: =NORMSDIST(NORMSINV(AQ11)-$E$11)/AQ11 -> 0.66803445
G35: 3 | H35: =NORMSDIST(NORMSINV(H12)-$E$12)/H12 -> 0.6678698 | I35: =NORMSDIST(NORMSINV(I12)-$E$12)/I12 -> 0.66803445 | J35: =NORMSDIST(NORMSINV(J12)-$E$12)/J12 -> 0.66761883 | K35: =NORMSDIST(NORMSINV(K12)-$E$12)/K12 -> 0.66795235 | L35: =NORMSDIST(NORMSINV(L12)-$E$12)/L12 -> 0.66753387 | M35: =NORMSDIST(NORMSINV(M12)-$E$12)/M12 -> 0.66744816 | N35: =NORMSDIST(NORMSINV(N12)-$E$12)/N12 -> 0.66744816 | O35: =NORMSDIST(NORMSINV(O12)-$E$12)/O12 -> 0.6677031 | ... AQ35: =NORMSDIST(NORMSINV(AQ12)-$E$12)/AQ12 -> 0.66803445
G36: 4 | H36: =NORMSDIST(NORMSINV(H13)-$E$13)/H13 -> 0.6678698 | I36: =NORMSDIST(NORMSINV(I13)-$E$13)/I13 -> 0.66803445 | J36: =NORMSDIST(NORMSINV(J13)-$E$13)/J13 -> 0.66761883 | K36: =NORMSDIST(NORMSINV(K13)-$E$13)/K13 -> 0.66795235 | L36: =NORMSDIST(NORMSINV(L13)-$E$13)/L13 -> 0.66753387 | M36: =NORMSDIST(NORMSINV(M13)-$E$13)/M13 -> 0.66744816 | N36: =NORMSDIST(NORMSINV(N13)-$E$13)/N13 -> 0.66744816 | O36: =NORMSDIST(NORMSINV(O13)-$E$13)/O13 -> 0.6677031 | ... AQ36: =NORMSDIST(NORMSINV(AQ13)-$E$13)/AQ13 -> 0.66803445
G37: 5 | H37: =NORMSDIST(NORMSINV(H14)-$E$14)/H14 -> 0.6678698 | I37: =NORMSDIST(NORMSINV(I14)-$E$14)/I14 -> 0.66803445 | J37: =NORMSDIST(NORMSINV(J14)-$E$14)/J14 -> 0.66761883 | K37: =NORMSDIST(NORMSINV(K14)-$E$14)/K14 -> 0.66795235 | L37: =NORMSDIST(NORMSINV(L14)-$E$14)/L14 -> 0.66753387 | M37: =NORMSDIST(NORMSINV(M14)-$E$14)/M14 -> 0.66744816 | N37: =NORMSDIST(NORMSINV(N14)-$E$14)/N14 -> 0.66744816 | O37: =NORMSDIST(NORMSINV(O14)-$E$14)/O14 -> 0.6677031 | ... AQ37: =NORMSDIST(NORMSINV(AQ14)-$E$14)/AQ14 -> 0.66803445
G38: 6 | H38: =NORMSDIST(NORMSINV(H15)-$E$15)/H15 -> 0.6678698 | I38: =NORMSDIST(NORMSINV(I15)-$E$15)/I15 -> 0.66803445 | J38: =NORMSDIST(NORMSINV(J15)-$E$15)/J15 -> 0.66761883 | K38: =NORMSDIST(NORMSINV(K15)-$E$15)/K15 -> 0.66795235 | L38: =NORMSDIST(NORMSINV(L15)-$E$15)/L15 -> 0.66753387 | M38: =NORMSDIST(NORMSINV(M15)-$E$15)/M15 -> 0.66744816 | N38: =NORMSDIST(NORMSINV(N15)-$E$15)/N15 -> 0.66744816 | O38: =NORMSDIST(NORMSINV(O15)-$E$15)/O15 -> 0.6677031 | ... AQ38: =NORMSDIST(NORMSINV(AQ15)-$E$15)/AQ15 -> 0.66803445
G39: 7 | H39: =NORMSDIST(NORMSINV(H16)-$E$16)/H16 -> 0.66775994 | I39: =NORMSDIST(NORMSINV(I16)-$E$16)/I16 -> 0.66795245 | J39: =NORMSDIST(NORMSINV(J16)-$E$16)/J16 -> 0.66746658 | K39: =NORMSDIST(NORMSINV(K16)-$E$16)/K16 -> 0.66785646 | L39: =NORMSDIST(NORMSINV(L16)-$E$16)/L16 -> 0.66736728 | M39: =NORMSDIST(NORMSINV(M16)-$E$16)/M16 -> 0.6672671 | N39: =NORMSDIST(NORMSINV(N16)-$E$16)/N16 -> 0.6672671 | O39: =NORMSDIST(NORMSINV(O16)-$E$16)/O16 -> 0.66756507 | ... AQ39: =NORMSDIST(NORMSINV(AQ16)-$E$16)/AQ16 -> 0.66795245
G40: 8 | H40: =NORMSDIST(NORMSINV(H17)-$E$17)/H17 -> 0.6676118 | I40: =NORMSDIST(NORMSINV(I17)-$E$17)/I17 -> 0.66784192 | J40: =NORMSDIST(NORMSINV(J17)-$E$17)/J17 -> 0.66726118 | K40: =NORMSDIST(NORMSINV(K17)-$E$17)/K17 -> 0.66772717 | L40: =NORMSDIST(NORMSINV(L17)-$E$17)/L17 -> 0.66714252 | M40: =NORMSDIST(NORMSINV(M17)-$E$17)/M17 -> 0.66702282 | N40: =NORMSDIST(NORMSINV(N17)-$E$17)/N17 -> 0.66702282 | O40: =NORMSDIST(NORMSINV(O17)-$E$17)/O17 -> 0.66737888 | ... AQ40: =NORMSDIST(NORMSINV(AQ17)-$E$17)/AQ17 -> 0.66784192
G41: 9 | H41: =NORMSDIST(NORMSINV(H18)-$E$18)/H18 -> 0.66756672 | I41: =NORMSDIST(NORMSINV(I18)-$E$18)/I18 -> 0.66780831 | J41: =NORMSDIST(NORMSINV(J18)-$E$18)/J18 -> 0.66719865 | K41: =NORMSDIST(NORMSINV(K18)-$E$18)/K18 -> 0.66768783 | L41: =NORMSDIST(NORMSINV(L18)-$E$18)/L18 -> 0.6670741 | M41: =NORMSDIST(NORMSINV(M18)-$E$18)/M18 -> 0.66694845 | N41: =NORMSDIST(NORMSINV(N18)-$E$18)/N18 -> 0.66694845 | O41: =NORMSDIST(NORMSINV(O18)-$E$18)/O18 -> 0.66732221 | ... AQ41: =NORMSDIST(NORMSINV(AQ18)-$E$18)/AQ18 -> 0.66780831
G42: 10 | H42: =NORMSDIST(NORMSINV(H19)-$E$19)/H19 -> 0.66738912 | I42: =NORMSDIST(NORMSINV(I19)-$E$19)/I19 -> 0.66767602 | J42: =NORMSDIST(NORMSINV(J19)-$E$19)/J19 -> 0.66695217 | K42: =NORMSDIST(NORMSINV(K19)-$E$19)/K19 -> 0.66753295 | L42: =NORMSDIST(NORMSINV(L19)-$E$19)/L19 -> 0.66680434 | M42: =NORMSDIST(NORMSINV(M19)-$E$19)/M19 -> 0.66665523 | N42: =NORMSDIST(NORMSINV(N19)-$E$19)/N19 -> 0.66665523 | O42: =NORMSDIST(NORMSINV(O19)-$E$19)/O19 -> 0.66709884 | ... AQ42: =NORMSDIST(NORMSINV(AQ19)-$E$19)/AQ19 -> 0.66767602
G43: 11 | H43: =NORMSDIST(NORMSINV(H20)-$E$20)/H20 -> 0.6671873 | I43: =NORMSDIST(NORMSINV(I20)-$E$20)/I20 -> 0.66752601 | J43: =NORMSDIST(NORMSINV(J20)-$E$20)/J20 -> 0.66667162 | K43: =NORMSDIST(NORMSINV(K20)-$E$20)/K20 -> 0.66735708 | L43: =NORMSDIST(NORMSINV(L20)-$E$20)/L20 -> 0.66649722 | M43: =NORMSDIST(NORMSINV(M20)-$E$20)/M20 -> 0.66632133 | N43: =NORMSDIST(NORMSINV(N20)-$E$20)/N20 -> 0.66632133 | O43: =NORMSDIST(NORMSINV(O20)-$E$20)/O20 -> 0.66684469 | ... AQ43: =NORMSDIST(NORMSINV(AQ20)-$E$20)/AQ20 -> 0.66752601
G44: 12 | H44: =NORMSDIST(NORMSINV(H21)-$E$21)/H21 -> 0.66695409 | I44: =NORMSDIST(NORMSINV(I21)-$E$21)/I21 -> 0.66735322 | J44: =NORMSDIST(NORMSINV(J21)-$E$21)/J21 -> 0.66634673 | K44: =NORMSDIST(NORMSINV(K21)-$E$21)/K21 -> 0.66715414 | L44: =NORMSDIST(NORMSINV(L21)-$E$21)/L21 -> 0.66614139 | M44: =NORMSDIST(NORMSINV(M21)-$E$21)/M21 -> 0.66593436 | N44: =NORMSDIST(NORMSINV(N21)-$E$21)/N21 -> 0.66593436 | O44: =NORMSDIST(NORMSINV(O21)-$E$21)/O21 -> 0.66655052 | ... AQ44: =NORMSDIST(NORMSINV(AQ21)-$E$21)/AQ21 -> 0.66735322
G45: 13 | H45: =NORMSDIST(NORMSINV(H22)-$E$22)/H22 -> 0.66670978 | I45: =NORMSDIST(NORMSINV(I22)-$E$22)/I22 -> 0.66717291 | J45: =NORMSDIST(NORMSINV(J22)-$E$22)/J22 -> 0.66600544 | K45: =NORMSDIST(NORMSINV(K22)-$E$22)/K22 -> 0.66694188 | L45: =NORMSDIST(NORMSINV(L22)-$E$22)/L22 -> 0.66576743 | M45: =NORMSDIST(NORMSINV(M22)-$E$22)/M22 -> 0.6655275 | N45: =NORMSDIST(NORMSINV(N22)-$E$22)/N22 -> 0.6655275 | O45: =NORMSDIST(NORMSINV(O22)-$E$22)/O22 -> 0.66624173 | ... AQ45: =NORMSDIST(NORMSINV(AQ22)-$E$22)/AQ22 -> 0.66717291
G46: 14 | H46: =NORMSDIST(NORMSINV(H23)-$E$23)/H23 -> 0.66632291 | I46: =NORMSDIST(NORMSINV(I23)-$E$23)/I23 -> 0.66688889 | J46: =NORMSDIST(NORMSINV(J23)-$E$23)/J23 -> 0.66546302 | K46: =NORMSDIST(NORMSINV(K23)-$E$23)/K23 -> 0.6666065 | L46: =NORMSDIST(NORMSINV(L23)-$E$23)/L23 -> 0.66517267 | M46: =NORMSDIST(NORMSINV(M23)-$E$23)/M23 -> 0.66488011 | N46: =NORMSDIST(NORMSINV(N23)-$E$23)/N23 -> 0.66488011 | O46: =NORMSDIST(NORMSINV(O23)-$E$23)/O23 -> 0.66575137 | ... AQ46: =NORMSDIST(NORMSINV(AQ23)-$E$23)/AQ23 -> 0.66688889
G47: 15 | H47: =NORMSDIST(NORMSINV(H24)-$E$24)/H24 -> 0.66555638 | I47: =NORMSDIST(NORMSINV(I24)-$E$24)/I24 -> 0.66633109 | J47: =NORMSDIST(NORMSINV(J24)-$E$24)/J24 -> 0.66438206 | K47: =NORMSDIST(NORMSINV(K24)-$E$24)/K24 -> 0.66594438 | L47: =NORMSDIST(NORMSINV(L24)-$E$24)/L24 -> 0.66398627 | M47: =NORMSDIST(NORMSINV(M24)-$E$24)/M24 -> 0.66358782 | N47: =NORMSDIST(NORMSINV(N24)-$E$24)/N24 -> 0.66358782 | O47: =NORMSDIST(NORMSINV(O24)-$E$24)/O24 -> 0.66477549 | ... AQ47: =NORMSDIST(NORMSINV(AQ24)-$E$24)/AQ24 -> 0.66633109
G48: 16 | H48: =NORMSDIST(NORMSINV(H25)-$E$25)/H25 -> 0.66365569 | I48: =NORMSDIST(NORMSINV(I25)-$E$25)/I25 -> 0.66496713 | J48: =NORMSDIST(NORMSINV(J25)-$E$25)/J25 -> 0.6616813 | K48: =NORMSDIST(NORMSINV(K25)-$E$25)/K25 -> 0.66431159 | L48: =NORMSDIST(NORMSINV(L25)-$E$25)/L25 -> 0.66101943 | M48: =NORMSDIST(NORMSINV(M25)-$E$25)/M25 -> 0.66035492 | N48: =NORMSDIST(NORMSINV(N25)-$E$25)/N25 -> 0.66035492 | O48: =NORMSDIST(NORMSINV(O25)-$E$25)/O25 -> 0.66234099 | ... AQ48: =NORMSDIST(NORMSINV(AQ25)-$E$25)/AQ25 -> 0.66496713
G49: 17 | H49: =NORMSDIST(NORMSINV(H26)-$E$26)/H26 -> 0.65800332 | I49: =NORMSDIST(NORMSINV(I26)-$E$26)/I26 -> 0.66095773 | J49: =NORMSDIST(NORMSINV(J26)-$E$26)/J26 -> 0.65366119 | K49: =NORMSDIST(NORMSINV(K26)-$E$26)/K26 -> 0.65947361 | L49: =NORMSDIST(NORMSINV(L26)-$E$26)/L26 -> 0.65223224 | M49: =NORMSDIST(NORMSINV(M26)-$E$26)/M26 -> 0.65081034 | N49: =NORMSDIST(NORMSINV(N26)-$E$26)/N26 -> 0.65081034 | O49: =NORMSDIST(NORMSINV(O26)-$E$26)/O26 -> 0.65509847 | ... AQ49: =NORMSDIST(NORMSINV(AQ26)-$E$26)/AQ26 -> 0.66095773

Sheet EAD Amort schedule
C3: Amount | D3: 100000
C4: Rate | D4: 0.12 | N4: 0.12149579
C6: Period | D6: Beg Bal (P) | E6: Principal | F6: SMM | G6: Prepayment | H6: Interest | I6: Total Prin | J6: End bal | K6: EAD | N6: -99400
C7: 1 | D7: 100000 | E7: =-PPMT($D$4/12,1,120-C7+1,D7,0) -> 434.70948 | F7: 0 | G7: 0 | H7: =-IPMT($D$4/12,1,120-C7+1,D7,0) -> 1000 | I7: =E7+G7 -> 434.70948 | J7: =D7-I7 -> 99565.291 | N7: 1434.7095
C8: 2 | D8: =J7 -> 99565.291 | E8: =-PPMT($D$4/12,1,120-C8+1,D8,0) -> 439.05658 | F8: 0 | G8: 0 | H8: =-IPMT($D$4/12,1,120-C8+1,D8,0) -> 995.65291 | I8: =E8+G8 -> 439.05658 | J8: =D8-I8 -> 99126.234 | N8: 1434.7095
C9: 3 | D9: =J8 -> 99126.234 | E9: =-PPMT($D$4/12,1,120-C9+1,D9,0) -> 443.44714 | F9: 0 | G9: 0 | H9: =-IPMT($D$4/12,1,120-C9+1,D9,0) -> 991.26234 | I9: =E9+G9 -> 443.44714 | J9: =D9-I9 -> 98682.787 | K9: =D7+3*D7*$D$4/12 -> 103000 | N9: 1434.7095
C10: 4 | D10: =J9 -> 98682.787 | E10: =-PPMT($D$4/12,1,120-C10+1,D10,0) -> 447.88162 | F10: 0 | G10: 0 | H10: =-IPMT($D$4/12,1,120-C10+1,D10,0) -> 986.82787 | I10: =E10+G10 -> 447.88162 | J10: =D10-I10 -> 98234.905 | N10: 1434.7095
C11: 5 | D11: =J10 -> 98234.905 | E11: =-PPMT($D$4/12,1,120-C11+1,D11,0) -> 452.36043 | F11: 0 | G11: 0 | H11: =-IPMT($D$4/12,1,120-C11+1,D11,0) -> 982.34905 | I11: =E11+G11 -> 452.36043 | J11: =D11-I11 -> 97782.545 | N11: 1434.7095
C12: 6 | D12: =J11 -> 97782.545 | E12: =-PPMT($D$4/12,1,120-C12+1,D12,0) -> 456.88404 | F12: 0 | G12: 0 | H12: =-IPMT($D$4/12,1,120-C12+1,D12,0) -> 977.82545 | I12: =E12+G12 -> 456.88404 | J12: =D12-I12 -> 97325.661 | K12: =D10+3*D10*$D$4/12 -> 101643.27 | N12: 1434.7095
C13: 7 | D13: =J12 -> 97325.661 | E13: =-PPMT($D$4/12,1,120-C13+1,D13,0) -> 461.45288 | F13: 0 | G13: 0 | H13: =-IPMT($D$4/12,1,120-C13+1,D13,0) -> 973.25661 | I13: =E13+G13 -> 461.45288 | J13: =D13-I13 -> 96864.208 | N13: 1434.7095
C14: 8 | D14: =J13 -> 96864.208 | E14: =-PPMT($D$4/12,1,120-C14+1,D14,0) -> 466.06741 | F14: 0 | G14: 0 | H14: =-IPMT($D$4/12,1,120-C14+1,D14,0) -> 968.64208 | I14: =E14+G14 -> 466.06741 | J14: =D14-I14 -> 96398.14 | N14: 1434.7095
C15: 9 | D15: =J14 -> 96398.14 | E15: =-PPMT($D$4/12,1,120-C15+1,D15,0) -> 470.72808 | F15: 0 | G15: 0 | H15: =-IPMT($D$4/12,1,120-C15+1,D15,0) -> 963.9814 | I15: =E15+G15 -> 470.72808 | J15: =D15-I15 -> 95927.412 | K15: =D13+3*D13*$D$4/12 -> 100245.43 | N15: 1434.7095
C16: 10 | D16: =J15 -> 95927.412 | E16: =-PPMT($D$4/12,1,120-C16+1,D16,0) -> 475.43536 | F16: 0 | G16: 0 | H16: =-IPMT($D$4/12,1,120-C16+1,D16,0) -> 959.27412 | I16: =E16+G16 -> 475.43536 | J16: =D16-I16 -> 95451.977 | N16: 1434.7095
C17: 11 | D17: =J16 -> 95451.977 | E17: =-PPMT($D$4/12,1,120-C17+1,D17,0) -> 480.18971 | F17: 0 | G17: 0 | H17: =-IPMT($D$4/12,1,120-C17+1,D17,0) -> 954.51977 | I17: =E17+G17 -> 480.18971 | J17: =D17-I17 -> 94971.787 | N17: 1434.7095
C18: 12 | D18: =J17 -> 94971.787 | E18: =-PPMT($D$4/12,1,120-C18+1,D18,0) -> 484.99161 | F18: 0 | G18: 0 | H18: =-IPMT($D$4/12,1,120-C18+1,D18,0) -> 949.71787 | I18: =E18+G18 -> 484.99161 | J18: =D18-I18 -> 94486.796 | K18: =D16+3*D16*$D$4/12 -> 98805.235 | N18: 1434.7095
C19: 13 | D19: =J18 -> 94486.796 | E19: =-PPMT($D$4/12,1,120-C19+1,D19,0) -> 489.84153 | F19: 0 | G19: 0 | H19: =-IPMT($D$4/12,1,120-C19+1,D19,0) -> 944.86796 | I19: =E19+G19 -> 489.84153 | J19: =D19-I19 -> 93996.954 | N19: 1434.7095
C20: 14 | D20: =J19 -> 93996.954 | E20: =-PPMT($D$4/12,1,120-C20+1,D20,0) -> 494.73994 | F20: 0 | G20: 0 | H20: =-IPMT($D$4/12,1,120-C20+1,D20,0) -> 939.96954 | I20: =E20+G20 -> 494.73994 | J20: =D20-I20 -> 93502.214 | N20: 1434.7095
C21: 15 | D21: =J20 -> 93502.214 | E21: =-PPMT($D$4/12,1,120-C21+1,D21,0) -> 499.68734 | F21: 0 | G21: 0 | H21: =-IPMT($D$4/12,1,120-C21+1,D21,0) -> 935.02214 | I21: =E21+G21 -> 499.68734 | J21: =D21-I21 -> 93002.527 | K21: =D19+3*D19*$D$4/12 -> 97321.4 | N21: 1434.7095
C22: 16 | D22: =J21 -> 93002.527 | E22: =-PPMT($D$4/12,1,120-C22+1,D22,0) -> 504.68422 | F22: 0 | G22: 0 | H22: =-IPMT($D$4/12,1,120-C22+1,D22,0) -> 930.02527 | I22: =E22+G22 -> 504.68422 | J22: =D22-I22 -> 92497.843 | N22: 1434.7095
C23: 17 | D23: =J22 -> 92497.843 | E23: =-PPMT($D$4/12,1,120-C23+1,D23,0) -> 509.73106 | F23: 0 | G23: 0 | H23: =-IPMT($D$4/12,1,120-C23+1,D23,0) -> 924.97843 | I23: =E23+G23 -> 509.73106 | J23: =D23-I23 -> 91988.112 | N23: 1434.7095
C24: 18 | D24: =J23 -> 91988.112 | E24: =-PPMT($D$4/12,1,120-C24+1,D24,0) -> 514.82837 | F24: 0 | G24: 0 | H24: =-IPMT($D$4/12,1,120-C24+1,D24,0) -> 919.88112 | I24: =E24+G24 -> 514.82837 | J24: =D24-I24 -> 91473.283 | K24: =D22+3*D22*$D$4/12 -> 95792.603 | N24: 1434.7095
C25: 19 | D25: =J24 -> 91473.283 | E25: =-PPMT($D$4/12,1,120-C25+1,D25,0) -> 519.97665 | F25: 0 | G25: 0 | H25: =-IPMT($D$4/12,1,120-C25+1,D25,0) -> 914.73283 | I25: =E25+G25 -> 519.97665 | J25: =D25-I25 -> 90953.307 | N25: 1434.7095
C26: 20 | D26: =J25 -> 90953.307 | E26: =-PPMT($D$4/12,1,120-C26+1,D26,0) -> 525.17642 | F26: 0 | G26: 0 | H26: =-IPMT($D$4/12,1,120-C26+1,D26,0) -> 909.53307 | I26: =E26+G26 -> 525.17642 | J26: =D26-I26 -> 90428.13 | N26: 1434.7095
C27: 21 | D27: =J26 -> 90428.13 | E27: =-PPMT($D$4/12,1,120-C27+1,D27,0) -> 530.42818 | F27: 0 | G27: 0 | H27: =-IPMT($D$4/12,1,120-C27+1,D27,0) -> 904.2813 | I27: =E27+G27 -> 530.42818 | J27: =D27-I27 -> 89897.702 | K27: =D25+3*D25*$D$4/12 -> 94217.482 | N27: 1434.7095
C28: 22 | D28: =J27 -> 89897.702 | E28: =-PPMT($D$4/12,1,120-C28+1,D28,0) -> 535.73246 | F28: 0 | G28: 0 | H28: =-IPMT($D$4/12,1,120-C28+1,D28,0) -> 898.97702 | I28: =E28+G28 -> 535.73246 | J28: =D28-I28 -> 89361.969 | N28: 1434.7095
C29: 23 | D29: =J28 -> 89361.969 | E29: =-PPMT($D$4/12,1,120-C29+1,D29,0) -> 541.08979 | F29: 0 | G29: 0 | H29: =-IPMT($D$4/12,1,120-C29+1,D29,0) -> 893.61969 | I29: =E29+G29 -> 541.08979 | J29: =D29-I29 -> 88820.88 | N29: 1434.7095
C30: 24 | D30: =J29 -> 88820.88 | E30: =-PPMT($D$4/12,1,120-C30+1,D30,0) -> 546.50069 | F30: 0 | G30: 0 | H30: =-IPMT($D$4/12,1,120-C30+1,D30,0) -> 888.2088 | I30: =E30+G30 -> 546.50069 | J30: =D30-I30 -> 88274.379 | K30: =D28+3*D28*$D$4/12 -> 92594.633 | N30: 1434.7095
C31: 25 | D31: =J30 -> 88274.379 | E31: =-PPMT($D$4/12,1,120-C31+1,D31,0) -> 551.96569 | F31: 0 | G31: 0 | H31: =-IPMT($D$4/12,1,120-C31+1,D31,0) -> 882.74379 | I31: =E31+G31 -> 551.96569 | J31: =D31-I31 -> 87722.413 | N31: 1434.7095
C32: 26 | D32: =J31 -> 87722.413 | E32: =-PPMT($D$4/12,1,120-C32+1,D32,0) -> 557.48535 | F32: 0 | G32: 0 | H32: =-IPMT($D$4/12,1,120-C32+1,D32,0) -> 877.22413 | I32: =E32+G32 -> 557.48535 | J32: =D32-I32 -> 87164.928 | N32: 1434.7095
C33: 27 | D33: =J32 -> 87164.928 | E33: =-PPMT($D$4/12,1,120-C33+1,D33,0) -> 563.0602 | F33: 0 | G33: 0 | H33: =-IPMT($D$4/12,1,120-C33+1,D33,0) -> 871.64928 | I33: =E33+G33 -> 563.0602 | J33: =D33-I33 -> 86601.868 | K33: =D31+3*D31*$D$4/12 -> 90922.61 | N33: 1434.7095
C34: 28 | D34: =J33 -> 86601.868 | E34: =-PPMT($D$4/12,1,120-C34+1,D34,0) -> 568.69081 | F34: 0 | G34: 0 | H34: =-IPMT($D$4/12,1,120-C34+1,D34,0) -> 866.01868 | I34: =E34+G34 -> 568.69081 | J34: =D34-I34 -> 86033.177 | N34: 1434.7095
C35: 29 | D35: =J34 -> 86033.177 | E35: =-PPMT($D$4/12,1,120-C35+1,D35,0) -> 574.37771 | F35: 0 | G35: 0 | H35: =-IPMT($D$4/12,1,120-C35+1,D35,0) -> 860.33177 | I35: =E35+G35 -> 574.37771 | J35: =D35-I35 -> 85458.799 | N35: 1434.7095
C36: 30 | D36: =J35 -> 85458.799 | E36: =-PPMT($D$4/12,1,120-C36+1,D36,0) -> 580.12149 | F36: 0 | G36: 0 | H36: =-IPMT($D$4/12,1,120-C36+1,D36,0) -> 854.58799 | I36: =E36+G36 -> 580.12149 | J36: =D36-I36 -> 84878.678 | K36: =D34+3*D34*$D$4/12 -> 89199.924 | N36: 1434.7095
C37: 31 | D37: =J36 -> 84878.678 | E37: =-PPMT($D$4/12,1,120-C37+1,D37,0) -> 585.92271 | F37: 0 | G37: 0 | H37: =-IPMT($D$4/12,1,120-C37+1,D37,0) -> 848.78678 | I37: =E37+G37 -> 585.92271 | J37: =D37-I37 -> 84292.755 | N37: 1434.7095
C38: 32 | D38: =J37 -> 84292.755 | E38: =-PPMT($D$4/12,1,120-C38+1,D38,0) -> 591.78193 | F38: 0 | G38: 0 | H38: =-IPMT($D$4/12,1,120-C38+1,D38,0) -> 842.92755 | I38: =E38+G38 -> 591.78193 | J38: =D38-I38 -> 83700.973 | N38: 1434.7095
C39: 33 | D39: =J38 -> 83700.973 | E39: =-PPMT($D$4/12,1,120-C39+1,D39,0) -> 597.69975 | F39: 0 | G39: 0 | H39: =-IPMT($D$4/12,1,120-C39+1,D39,0) -> 837.00973 | I39: =E39+G39 -> 597.69975 | J39: =D39-I39 -> 83103.273 | K39: =D37+3*D37*$D$4/12 -> 87425.038 | N39: 1434.7095
C40: 34 | D40: =J39 -> 83103.273 | E40: =-PPMT($D$4/12,1,120-C40+1,D40,0) -> 603.67675 | F40: 0 | G40: 0 | H40: =-IPMT($D$4/12,1,120-C40+1,D40,0) -> 831.03273 | I40: =E40+G40 -> 603.67675 | J40: =D40-I40 -> 82499.597 | N40: 1434.7095
C41: 35 | D41: =J40 -> 82499.597 | E41: =-PPMT($D$4/12,1,120-C41+1,D41,0) -> 609.71352 | F41: 0 | G41: 0 | H41: =-IPMT($D$4/12,1,120-C41+1,D41,0) -> 824.99597 | I41: =E41+G41 -> 609.71352 | J41: =D41-I41 -> 81889.883 | N41: 1434.7095
C42: 36 | D42: =J41 -> 81889.883 | E42: =-PPMT($D$4/12,1,120-C42+1,D42,0) -> 615.81065 | F42: 0 | G42: 0 | H42: =-IPMT($D$4/12,1,120-C42+1,D42,0) -> 818.89883 | I42: =E42+G42 -> 615.81065 | J42: =D42-I42 -> 81274.072 | K42: =D40+3*D40*$D$4/12 -> 85596.372 | N42: 1434.7095
C43: 37 | D43: =J42 -> 81274.072 | E43: =-PPMT($D$4/12,1,120-C43+1,D43,0) -> 621.96876 | F43: 0 | G43: 0 | H43: =-IPMT($D$4/12,1,120-C43+1,D43,0) -> 812.74072 | I43: =E43+G43 -> 621.96876 | J43: =D43-I43 -> 80652.104 | N43: 1434.7095
...

Sheet LGD_Secured
D2: a | E2: 0.75 | F2: 25% cure rate | K2: LGD = a.Max(LTV-0.7,0)
D3: b | E3: 0.8 | F3: Haircut of 20% (sale price is 80% of MV)
D4: c | E4: 0.7 | F4: Max LTV at which there is no loss
D6: 1 | E6: 2 | F6: 3 | G6: 4 | H6: 5 | I6: 6 | J6: 7 | K6: 8 | L6: 9 | M6: 10 | N6: 11 | O6: 12 | P6: 13 | Q6: 14 | R6: 15 | S6: 16 | T6: 17 | U6: 18 | V6: 19 | W6: 20 | X6: 21 | Y6: 22 | Z6: 23 | AA6: 24 | AB6: 25 | AC6: 26 | AD6: 27 | AE6: 28 | AF6: 29 | AG6: 30 | AH6: 31 | AI6: 32 | AJ6: 33 | AK6: 34 | AL6: 35 | AM6: 36
C7: After one year Quarterly Freq. | D7: 15 | E7: 18 | F7: 21 | G7: 24 | H7: 27 | I7: 30 | J7: 33 | K7: 36 | L7: 39 | M7: 42 | N7: 45 | O7: 48 | P7: 51 | Q7: 54 | R7: 57 | S7: 60 | T7: 63 | U7: 66 | V7: 69 | W7: 72 | X7: 75 | Y7: 78 | Z7: 81 | AA7: 84 | AB7: 87 | AC7: 90 | AD7: 93 | AE7: 96 | AF7: 99 | AG7: 102 | AH7: 105 | AI7: 108 | AJ7: 111 | AK7: 114 | AL7: 117 | AM7: 120
C8: EAD | D8: =VLOOKUP(D7,'EAD Amort schedule'!$C$7:$K$126,9,0) -> 97321.4 | E8: =VLOOKUP(E7,'EAD Amort schedule'!$C$7:$K$126,9,0) -> 95792.603 | F8: =VLOOKUP(F7,'EAD Amort schedule'!$C$7:$K$126,9,0) -> 94217.482 | G8: =VLOOKUP(G7,'EAD Amort schedule'!$C$7:$K$126,9,0) -> 92594.633 | H8: =VLOOKUP(H7,'EAD Amort schedule'!$C$7:$K$126,9,0) -> 90922.61 | I8: =VLOOKUP(I7,'EAD Amort schedule'!$C$7:$K$126,9,0) -> 89199.924 | J8: =VLOOKUP(J7,'EAD Amort schedule'!$C$7:$K$126,9,0) -> 87425.038 | K8: =VLOOKUP(K7,'EAD Amort schedule'!$C$7:$K$126,9,0) -> 85596.372 | ... AM8: =VLOOKUP(AM7,'EAD Amort schedule'!$C$7:$K$126,9,0) -> 4346.0432
C9: Collateral at beg | D9: 75000 | E9: 75237.249 | F9: 75499.828 | G9: 75701.523 | H9: 75953.36 | I9: 76143.746 | J9: 76322.007 | K9: 76500.687 | L9: 76717.627 | M9: 76858.766 | N9: 77076.722 | O9: 77244.355 | P9: 77450.711 | Q9: 77619.157 | R9: 77775.001 | S9: 78021.028 | T9: 78229.458 | U9: 78386.527 | V9: 78660.097 | W9: 78844.25 | X9: 79119.418 | Y9: 79395.546 | Z9: 79672.637 | AA9: 79950.696 | AB9: 80229.725 | AC9: 80509.728 | AD9: 80790.708 | AE9: 81072.669 | AF9: 81355.614 | AG9: 81639.546 | AH9: 81924.469 | AI9: 82210.387 | AJ9: 82497.302 | AK9: 82785.219 | AL9: 83074.14 | AM9: 83364.07
C10: Quartely HPI Growth (Base scenario) | D10: 0.0031633165 | E10: 0.0034900144 | F10: 0.0026714628 | G10: 0.0033267168 | H10: 0.0025066086 | I10: 0.0023411221 | J10: 0.0023411221 | K10: 0.0028357943 | L10: 0.0018397243 | M10: 0.0028357943 | N10: 0.0021748906 | O10: 0.0026714628 | P10: 0.0021748906 | Q10: 0.002007798 | R10: 0.0031633165 | S10: 0.0026714628 | T10: 0.002007798 | U10: 0.0034900144 | V10: 0.0023411221 | W10: 0.0034900144 | X10: 0.0034900144 | Y10: 0.0034900144 | Z10: 0.0034900144 | AA10: 0.0034900144 | AB10: 0.0034900144 | AC10: 0.0034900144 | AD10: 0.0034900144 | AE10: 0.0034900144 | AF10: 0.0034900144 | AG10: 0.0034900144 | AH10: 0.0034900144 | AI10: 0.0034900144 | AJ10: 0.0034900144 | AK10: 0.0034900144 | AL10: 0.0034900144 | AM10: 0.0034900144
C12: Collateral at end | D12: =D9*(1+D10) -> 75237.249 | E12: =E9*(1+E10) -> 75499.828 | F12: =F9*(1+F10) -> 75701.523 | G12: =G9*(1+G10) -> 75953.36 | H12: =H9*(1+H10) -> 76143.746 | I12: =I9*(1+I10) -> 76322.007 | J12: =J9*(1+J10) -> 76500.687 | K12: =K9*(1+K10) -> 76717.627 | ... AM12: =AM9*(1+AM10) -> 83655.012
C13: Sale Price | D13: =D12*$E$3 -> 60189.799 | E13: =E12*$E$3 -> 60399.862 | F13: =F12*$E$3 -> 60561.218 | G13: =G12*$E$3 -> 60762.688 | H13: =H12*$E$3 -> 60914.997 | I13: =I12*$E$3 -> 61057.606 | J13: =J12*$E$3 -> 61200.549 | K13: =K12*$E$3 -> 61374.101 | ... AM13: =AM12*$E$3 -> 66924.01
C14: LTV | D14: =D8/D13 -> 1.6169085 | E14: =E8/E13 -> 1.5859739 | F14: =F8/F13 -> 1.5557395 | G14: =G8/G13 -> 1.5238732 | H14: =H8/H13 -> 1.4926146 | I14: =I8/I13 -> 1.4609142 | J14: =J8/J13 -> 1.4285009 | K14: =K8/K13 -> 1.394666 | ... AM14: =AM8/AM13 -> 0.064939969
C16: LGD | D16: =$E$2*MAX(D14-$E$4,0) -> 0.6876814 | E16: =$E$2*MAX(E14-$E$4,0) -> 0.66448039 | F16: =$E$2*MAX(F14-$E$4,0) -> 0.64180465 | G16: =$E$2*MAX(G14-$E$4,0) -> 0.61790491 | H16: =$E$2*MAX(H14-$E$4,0) -> 0.59446092 | I16: =$E$2*MAX(I14-$E$4,0) -> 0.57068565 | J16: =$E$2*MAX(J14-$E$4,0) -> 0.54637565 | K16: =$E$2*MAX(K14-$E$4,0) -> 0.52099949 | ... AM16: =$E$2*MAX(AM14-$E$4,0) -> 0
C19: Note | D19: Haircut and cure can be modelled as per difference economic conditions

Sheet Sheet 1

Sheet Sheet 2
B2: Default | C2: Sno | R2: 1 | S2: 0
B3: #REF! | C3: 1 | E3: #REF! | F3: #REF! | G3: 37895 | I3: #REF! | J3: #REF! | K3: 37895 | M3: #REF! | N3: 37895 | Q3: 37895 | R3: 12 | S3: 313 | T3: 1
G4: 37895 | K4: 37895 | M4: #REF! | N4: 37895 | Q4: 37987 | R4: 11 | S4: 299 | T4: 2
G5: 37895 | K5: 37895 | M5: #N/A | N5: 37895 | Q5: 38078 | R5: 10 | S5: 297 | T5: 3
G6: 37895 | K6: 37895 | M6: #N/A | N6: 37895 | Q6: 38169 | R6: 10 | S6: 325 | T6: 4
G7: 37895 | K7: 37895 | M7: #N/A | N7: 37895 | Q7: 38261 | R7: 9 | S7: 307 | T7: 5
G8: 37895 | K8: 37895 | M8: #N/A | N8: 37895 | Q8: 38353 | R8: 9 | S8: 300 | T8: 6
G9: 37895 | K9: 37895 | M9: #N/A | N9: 37895 | Q9: 38443 | R9: 9 | S9: 321 | T9: 7
G10: 37895 | K10: 37895 | M10: #N/A | N10: 37895 | Q10: 38534 | R10: 9 | S10: 307 | T10: 8
G11: 37895 | K11: 37895 | M11: #N/A | N11: 37895 | Q11: 38626 | R11: 9 | S11: 334 | T11: 9
G12: 37895 | K12: 37895 | M12: #N/A | N12: 37895 | Q12: 38718 | R12: 9 | S12: 334 | T12: 10
G13: 37895 | K13: 37895 | M13: #N/A | N13: 37895 | Q13: 38808 | R13: 9 | S13: 315 | T13: 11
G14: 37895 | K14: 37895 | M14: #N/A | N14: 37895 | Q14: 38899 | R14: 9 | S14: 305 | T14: 12
G15: 37987 | K15: 37895 | M15: #N/A | N15: 37987 | Q15: 38991 | R15: 10 | S15: 326 | T15: 13
... G80: 38534 | K80: 37895 | M80: #N/A | N80: 38534 | Q80: 44927 | R80: 9 | S80: 337 | T80: 78
G81: 38534 | K81: 37895 | M81: #N/A | N81: 38534 | Q81: 45017 | T81: 79
G82: 38626 | K82: 37895 | M82: #N/A | N82: 38626
G83: 38626 | K83: 37895 | M83: #N/A | N83: 38626
G84: 38626 | K84: 37895 | M84: #N/A | N84: 38626
G85: 38626 | K85: 37895 | M85: #N/A | N85: 38626
G86: 38626 | K86: 37895 | M86: #N/A | N86: 38626
G87: 38626 | K87: 37895 | M87: #N/A | N87: 38626
G88: 38626 | K88: 37895 | M88: #N/A | N88: 38626
G89: 38626 | K89: 37895 | M89: #N/A | N89: 38626
G90: 38626 | K90: 37895 | M90: #N/A | N90: 38626
G91: 38718 | K91: 37895 | M91: #N/A | N91: 38718
G92: 38718 | K92: 37895 | M92: #N/A | N92: 38718
G93: 38718 | K93: 37895 | M93: #N/A | N93: 38718
... G1334: 44927 | K1334: 38261 | M1334: #N/A | N1334: 44927
K1335: 38261 | M1335: #N/A | N1335: 37895
K1336: 38261 | M1336: #N/A | N1336: 37895
K1337: 38261 | M1337: #N/A | N1337: 37895
K1338: 38261 | M1338: #N/A | N1338: 37895
K1339: 38261 | M1339: #N/A | N1339: 37895
K1340: 38261 | M1340: #N/A | N1340: 37895
K1341: 38261 | M1341: #N/A | N1341: 37895
K1342: 38261 | M1342: #N/A | N1342: 37895
K1343: 38261 | M1343: #N/A | N1343: 37895
K1344: 38261 | M1344: #N/A | N1344: 37895
K1345: 38261 | M1345: #N/A | N1345: 37895
...

Sheet Sheet 3

Sheet Sheet 4
