Workbook

Sheet Objective

Sheet MODEL
L2: Value: -Inf to + Inf | M2: 0 to 1 | N2: 0 to 1 | Q2: Equation = 487.123+(28.853)*Log (1-Sigmoid)/Log Sigmoid | U2: SUM of LL | V2: =SUM(O4:O1503) -> -687.2214
B3: customer | C3: age | D3: ed | E3: employ | F3: address | G3: income | H3: debtinc | I3: creddebt | J3: othdebt | K3: default | L3: Log Odds (Y Hat) | M3: Sigmoid | N3: Likelihood | O3: LL | P3: Default P | Q3: Score | R3: Grade_1 | S3: Grade_2 | Y3: b0 | Z3: b1 | AA3: b2 | AB3: b3 | AC3: b4 | AD3: b5 | AE3: b6 | AF3: b7 | AG3: b8 | AW3: branch | AX3: branch code
B4: 10012 | C4: 28 | D4: 2 | E4: 7 | F4: 2 | G4: 44 | H4: 17.7 | I4: 2.99 | J4: 4.8 | K4: 0 | L4: =$Y$4+SUMPRODUCT($Z$4:$AG$4,C4:J4) -> 0.54830274 | M4: =EXP(L4)/(1+EXP(L4)) -> 0.63374172 | N4: =IF(K4=1,M4,(1-M4)) -> 0.36625828 | O4: =LN(N4) -> -1.0044165 | P4: =IF(M4>0.4,1,0) -> 1 | Q4: =28.8539*LN((1-M4)/(M4))+487.123 -> 471.30233 | R4: =VLOOKUP(M4,$U$9:$W$16,3,TRUE) -> 7 | S4: =VLOOKUP(M4,$U$21:$W$37,3,TRUE) -> 15 | U4: MIN | V4: =MIN($Q$4:$Q$1503) -> 59.604795 | Y4: -0.40142318 | Z4: -0.021599275 | AA4: -0.053420436 | AB4: -0.22624294 | AC4: -0.032578078 | AD4: 0.00022085568 | AE4: 0.099623802 | AF4: 0.47373013 | AG4: 0.025143998 | AW4: ncust | AX4: number of customers
B5: 10017 | C5: 64 | D5: 5 | E5: 34 | F5: 17 | G5: 116 | H5: 14.7 | I5: 5.05 | J5: 12 | K5: 0 | L5: =$Y$4+SUMPRODUCT($Z$4:$AG$4,C5:J5) -> -6.112812 | M5: =EXP(L5)/(1+EXP(L5)) -> 0.0022094231 | N5: =IF(K5=1,M5,(1-M5)) -> 0.99779058 | O5: =LN(N5) -> -0.0022118675 | P5: =IF(M5>0.4,1,0) -> 0 | Q5: =28.8539*LN((1-M5)/(M5))+487.123 -> 663.50147 | R5: =VLOOKUP(M5,$U$9:$W$16,3,TRUE) -> 2 | S5: =VLOOKUP(M5,$U$21:$W$37,3,TRUE) -> 1 | U5: MAX | V5: =MAX($Q$4:$Q$1503) -> 849.91916 | AB5: -0.62766612 | AG5: -0.37627918 | AK5: 55 | AL5: 850 | AV5: b1 | AW5: age | AX5: age of the borrower
B6: 10030 | C6: 40 | D6: 1 | E6: 20 | F6: 12 | G6: 61 | H6: 4.8 | I6: 1.04 | J6: 1.89 | K6: 0 | L6: =$Y$4+SUMPRODUCT($Z$4:$AG$4,C6:J6) -> -5.2027424 | M6: =EXP(L6)/(1+EXP(L6)) -> 0.005471356 | N6: =IF(K6=1,M6,(1-M6)) -> 0.99452864 | O6: =LN(N6) -> -0.0054863787 | P6: =IF(M6>0.4,1,0) -> 0 | Q6: =28.8539*LN((1-M6)/(M6))+487.123 -> 637.24241 | R6: =VLOOKUP(M6,$U$9:$W$16,3,TRUE) -> 3 | S6: =VLOOKUP(M6,$U$21:$W$37,3,TRUE) -> 4 | Y6: 0.40097045 | AB6: 0.34803993 | AG6: 0.40702463 | AK6: =AL5-AK5 -> 795 | AV6: b2 | AW6: ed | AX6: educational qualification based on degrees
B7: 10039 | C7: 30 | D7: 1 | E7: 11 | F7: 3 | G7: 27 | H7: 34.5 | I7: 1.75 | J7: 7.56 | K7: 0 | L7: =$Y$4+SUMPRODUCT($Z$4:$AG$4,C7:J7) -> 0.77287218 | M7: =EXP(L7)/(1+EXP(L7)) -> 0.68414188 | N7: =IF(K7=1,M7,(1-M7)) -> 0.31585812 | O7: =LN(N7) -> -1.1524621 | P7: =IF(M7>0.4,1,0) -> 1 | Q7: =28.8539*LN((1-M7)/(M7))+487.123 -> 464.82262 | R7: =VLOOKUP(M7,$U$9:$W$16,3,TRUE) -> 8 | S7: =VLOOKUP(M7,$U$21:$W$37,3,TRUE) -> 15 | U7: GRADE_1 | AB7: -0.052930528 | AG7: 0.006054172 | AK7: =AK6/50 -> 15.9 | AV7: b3 | AW7: employ | AX7: number of years in the job
B8: 10069 | C8: 25 | D8: 1 | E8: 2 | F8: 2 | G8: 30 | H8: 22.4 | I8: 0.76 | J8: 5.96 | K8: 1 | L8: =$Y$4+SUMPRODUCT($Z$4:$AG$4,C8:J8) -> 1.2356244 | M8: =EXP(L8)/(1+EXP(L8)) -> 0.77480147 | N8: =IF(K8=1,M8,(1-M8)) -> 0.77480147 | O8: =LN(N8) -> -0.25514846 | P8: =IF(M8>0.4,1,0) -> 1 | Q8: =28.8539*LN((1-M8)/(M8))+487.123 -> 451.47042 | R8: =VLOOKUP(M8,$U$9:$W$16,3,TRUE) -> 8 | S8: =VLOOKUP(M8,$U$21:$W$37,3,TRUE) -> 16 | U8: LL Prob | V8: UP Prob | W8: Grade | AV8: b4 | AW8: address | AX8: number of years in the current address
B9: 10071 | C9: 35 | D9: 1 | E9: 2 | F9: 9 | G9: 38 | H9: 10.9 | I9: 1.46 | J9: 2.68 | K9: 1 | L9: =$Y$4+SUMPRODUCT($Z$4:$AG$4,C9:J9) -> -0.10318296 | M9: =EXP(L9)/(1+EXP(L9)) -> 0.47422712 | N9: =IF(K9=1,M9,(1-M9)) -> 0.47422712 | O9: =LN(N9) -> -0.74606891 | P9: =IF(M9>0.4,1,0) -> 1 | Q9: =28.8539*LN((1-M9)/(M9))+487.123 -> 490.10023 | R9: =VLOOKUP(M9,$U$9:$W$16,3,TRUE) -> 7 | S9: =VLOOKUP(M9,$U$21:$W$37,3,TRUE) -> 15 | U9: 0 | V9: 0.0015120307 | W9: 1 | Y9: Cut Off | Z9: TP | AA9: FP | AB9: TN | AC9: FN | AD9: FPR | AE9: TPR | AV9: b5 | AW9: income | AX9: income in '000$
B10: 10096 | C10: 26 | D10: 3 | E10: 2 | F10: 4 | G10: 38 | H10: 11.9 | I10: 0.95 | J10: 3.57 | K10: 1 | L10: =$Y$4+SUMPRODUCT($Z$4:$AG$4,C10:J10) -> 0.027659629 | M10: =EXP(L10)/(1+EXP(L10)) -> 0.50691447 | N10: =IF(K10=1,M10,(1-M10)) -> 0.50691447 | O10: =LN(N10) -> -0.67941299 | P10: =IF(M10>0.4,1,0) -> 1 | Q10: =28.8539*LN((1-M10)/(M10))+487.123 -> 486.32491 | R10: =VLOOKUP(M10,$U$9:$W$16,3,TRUE) -> 7 | S10: =VLOOKUP(M10,$U$21:$W$37,3,TRUE) -> 15 | U10: 0.0015120307 | V10: 0.0032075015 | W10: 2 | Y10: 0 | Z10: 548 | AA10: 952 | AB10: 0 | AC10: 0 | AD10: 1 | AE10: 1 | AF10: 1 | AG10: 0 | AV10: b6 | AW10: debtinc | AX10: debt to income ratio (or burden) in %
B11: 10128 | C11: 25 | D11: 1 | E11: 4 | F11: 2 | G11: 30 | H11: 14.4 | I11: 1.05 | J11: 3.27 | K11: 0 | L11: =$Y$4+SUMPRODUCT($Z$4:$AG$4,C11:J11) -> 0.055892524 | M11: =EXP(L11)/(1+EXP(L11)) -> 0.51396949 | N11: =IF(K11=1,M11,(1-M11)) -> 0.48603051 | O11: =LN(N11) -> -0.72148389 | P11: =IF(M11>0.4,1,0) -> 1 | Q11: =28.8539*LN((1-M11)/(M11))+487.123 -> 485.51028 | R11: =VLOOKUP(M11,$U$9:$W$16,3,TRUE) -> 7 | S11: =VLOOKUP(M11,$U$21:$W$37,3,TRUE) -> 15 | U11: 0.0032075015 | V11: 0.0096225045 | W11: 3 | Y11: 0.1 | Z11: 537 | AA11: 630 | AB11: 322 | AC11: 11 | AD11: 0.66176471 | AE11: 0.97992701 | AF11: 0.66176471 | AG11: 0.3181623 | AV11: b7 | AW11: creddebt | AX11: credit card debt in '000$
B12: 10129 | C12: 65 | D12: 4 | E12: 29 | F12: 14 | G12: 189 | H12: 5 | I12: 3.36 | J12: 6.09 | K12: 0 | L12: =$Y$4+SUMPRODUCT($Z$4:$AG$4,C12:J12) -> -6.7514752 | M12: =EXP(L12)/(1+EXP(L12)) -> 0.0011677882 | N12: =IF(K12=1,M12,(1-M12)) -> 0.99883221 | O12: =LN(N12) -> -0.0011684706 | P12: =IF(M12>0.4,1,0) -> 0 | Q12: =28.8539*LN((1-M12)/(M12))+487.123 -> 681.92939 | R12: =VLOOKUP(M12,$U$9:$W$16,3,TRUE) -> 1 | S12: =VLOOKUP(M12,$U$21:$W$37,3,TRUE) -> 1 | U12: 0.0096225045 | V12: 0.028867513 | W12: 4 | Y12: 0.2 | Z12: 507 | AA12: 468 | AB12: 484 | AC12: 41 | AD12: 0.49159664 | AE12: 0.92518248 | AF12: 0.49159664 | AG12: 0.43358584 | AV12: b8 | AW12: othdebt | AX12: other debt in $mn
B13: 10140 | C13: 21 | D13: 3 | E13: 0 | F13: 0 | G13: 23 | H13: 3.9 | I13: 0.31 | J13: 0.59 | K13: 0 | L13: =$Y$4+SUMPRODUCT($Z$4:$AG$4,C13:J13) -> -0.45996545 | M13: =EXP(L13)/(1+EXP(L13)) -> 0.38699402 | N13: =IF(K13=1,M13,(1-M13)) -> 0.61300598 | O13: =LN(N13) -> -0.48938059 | P13: =IF(M13>0.4,1,0) -> 0 | Q13: =28.8539*LN((1-M13)/(M13))+487.123 -> 500.3948 | R13: =VLOOKUP(M13,$U$9:$W$16,3,TRUE) -> 7 | S13: =VLOOKUP(M13,$U$21:$W$37,3,TRUE) -> 14 | U13: 0.028867513 | V13: 0.08660254 | W13: 5 | Y13: 0.3 | Z13: 466 | AA13: 335 | AB13: 617 | AC13: 82 | AD13: 0.35189076 | AE13: 0.85036496 | AF13: 0.35189076 | AG13: 0.49847421 | AW13: default | AX13: dummy for default incidents
B14: 10142 | C14: 62 | D14: 1 | E14: 33 | F14: 13 | G14: 96 | H14: 17.5 | I14: 6.69 | J14: 10.11 | K14: 0 | L14: =$Y$4+SUMPRODUCT($Z$4:$AG$4,C14:J14) -> -4.4954516 | M14: =EXP(L14)/(1+EXP(L14)) -> 0.011036476 | N14: =IF(K14=1,M14,(1-M14)) -> 0.98896352 | O14: =LN(N14) -> -0.01109783 | P14: =IF(M14>0.4,1,0) -> 0 | Q14: =28.8539*LN((1-M14)/(M14))+487.123 -> 616.83431 | R14: =VLOOKUP(M14,$U$9:$W$16,3,TRUE) -> 4 | S14: =VLOOKUP(M14,$U$21:$W$37,3,TRUE) -> 5 | U14: 0.08660254 | V14: 0.25980762 | W14: 6 | Y14: 0.4 | Z14: 403 | AA14: 222 | AB14: 730 | AC14: 145 | AD14: 0.23319328 | AE14: 0.73540146 | AF14: 0.23319328 | AG14: 0.50220818
B15: 10169 | C15: 30 | D15: 4 | E15: 4 | F15: 3 | G15: 39 | H15: 10.6 | I15: 2.39 | J15: 1.74 | K15: 1 | L15: =$Y$4+SUMPRODUCT($Z$4:$AG$4,C15:J15) -> -0.025197925 | M15: =EXP(L15)/(1+EXP(L15)) -> 0.49370085 | N15: =IF(K15=1,M15,(1-M15)) -> 0.49370085 | O15: =LN(N15) -> -0.70582551 | P15: =IF(M15>0.4,1,0) -> 1 | Q15: =28.8539*LN((1-M15)/(M15))+487.123 -> 487.85006 | R15: =VLOOKUP(M15,$U$9:$W$16,3,TRUE) -> 7 | S15: =VLOOKUP(M15,$U$21:$W$37,3,TRUE) -> 15 | U15: 0.25980762 | V15: 0.67082039 | W15: 7 | Y15: 0.5 | Z15: 327 | AA15: 132 | AB15: 820 | AC15: 221 | AD15: 0.13865546 | AE15: 0.59671533 | AF15: 0.13865546 | AG15: 0.45805987
B16: 10197 | C16: 38 | D16: 5 | E16: 7 | F16: 7 | G16: 124 | H16: 19.1 | I16: 9.52 | J16: 14.16 | K16: 0 | L16: =$Y$4+SUMPRODUCT($Z$4:$AG$4,C16:J16) -> 3.4951056 | M16: =EXP(L16)/(1+EXP(L16)) -> 0.97054819 | N16: =IF(K16=1,M16,(1-M16)) -> 0.029451811 | O16: =LN(N16) -> -3.5249999 | P16: =IF(M16>0.4,1,0) -> 1 | Q16: =28.8539*LN((1-M16)/(M16))+487.123 -> 386.27557 | R16: =VLOOKUP(M16,$U$9:$W$16,3,TRUE) -> 8 | S16: =VLOOKUP(M16,$U$21:$W$37,3,TRUE) -> 17 | U16: 0.67082039 | V16: 1 | W16: 8 | Y16: 0.6 | Z16: 257 | AA16: 70 | AB16: 882 | AC16: 291 | AD16: 0.073529412 | AE16: 0.4689781 | AF16: 0.073529412 | AG16: 0.39544869
B17: 10200 | C17: 18 | D17: 2 | E17: 0 | F17: 0 | G17: 35 | H17: 3.9 | I17: 0.17 | J17: 1.19 | K17: 0 | L17: =$Y$4+SUMPRODUCT($Z$4:$AG$4,C17:J17) -> -0.39033274 | M17: =EXP(L17)/(1+EXP(L17)) -> 0.4036372 | N17: =IF(K17=1,M17,(1-M17)) -> 0.5963628 | O17: =LN(N17) -> -0.51690608 | P17: =IF(M17>0.4,1,0) -> 1 | Q17: =28.8539*LN((1-M17)/(M17))+487.123 -> 498.38562 | R17: =VLOOKUP(M17,$U$9:$W$16,3,TRUE) -> 7 | S17: =VLOOKUP(M17,$U$21:$W$37,3,TRUE) -> 14 | Y17: 0.7 | Z17: 198 | AA17: 31 | AB17: 921 | AC17: 350 | AD17: 0.032563025 | AE17: 0.36131387 | AF17: 0.032563025 | AG17: 0.32875084
B18: 10218 | C18: 53 | D18: 1 | E18: 9 | F18: 13 | G18: 41 | H18: 13.3 | I18: 2.33 | J18: 3.12 | K18: 0 | L18: =$Y$4+SUMPRODUCT($Z$4:$AG$4,C18:J18) -> -1.5430145 | M18: =EXP(L18)/(1+EXP(L18)) -> 0.17609748 | N18: =IF(K18=1,M18,(1-M18)) -> 0.82390252 | O18: =LN(N18) -> -0.19370305 | P18: =IF(M18>0.4,1,0) -> 0 | Q18: =28.8539*LN((1-M18)/(M18))+487.123 -> 531.64499 | R18: =VLOOKUP(M18,$U$9:$W$16,3,TRUE) -> 6 | S18: =VLOOKUP(M18,$U$21:$W$37,3,TRUE) -> 12 | Y18: 0.8 | Z18: 137 | AA18: 9 | AB18: 943 | AC18: 411 | AD18: 0.0094537815 | AE18: 0.25 | AF18: 0.0094537815 | AG18: 0.24054622
B19: 10234 | C19: 18 | D19: 2 | E19: 0 | F19: 0 | G19: 15 | H19: 7.4 | I19: 0.83 | J19: 0.28 | K19: 1 | L19: =$Y$4+SUMPRODUCT($Z$4:$AG$4,C19:J19) -> 0.2437143 | M19: =EXP(L19)/(1+EXP(L19)) -> 0.56062878 | N19: =IF(K19=1,M19,(1-M19)) -> 0.56062878 | O19: =LN(N19) -> -0.57869631 | P19: =IF(M19>0.4,1,0) -> 1 | Q19: =28.8539*LN((1-M19)/(M19))+487.123 -> 480.09089 | R19: =VLOOKUP(M19,$U$9:$W$16,3,TRUE) -> 7 | S19: =VLOOKUP(M19,$U$21:$W$37,3,TRUE) -> 15 | U19: GRADE_2 | Y19: 0.9 | Z19: 68 | AA19: 4 | AB19: 948 | AC19: 480 | AD19: 0.0042016807 | AE19: 0.12408759 | AF19: 0.0042016807 | AG19: 0.11988591
B20: 10351 | C20: 18 | D20: 2 | E20: 0 | F20: 0 | G20: 56 | H20: 15.7 | I20: 1.84 | J20: 6.95 | K20: 1 | L20: =$Y$4+SUMPRODUCT($Z$4:$AG$4,C20:J20) -> 1.7258248 | M20: =EXP(L20)/(1+EXP(L20)) -> 0.84887759 | N20: =IF(K20=1,M20,(1-M20)) -> 0.84887759 | O20: =LN(N20) -> -0.16384028 | P20: =IF(M20>0.4,1,0) -> 1 | Q20: =28.8539*LN((1-M20)/(M20))+487.123 -> 437.32622 | R20: =VLOOKUP(M20,$U$9:$W$16,3,TRUE) -> 8 | S20: =VLOOKUP(M20,$U$21:$W$37,3,TRUE) -> 16 | U20: LB | V20: UB | W20: Grade | Y20: 1 | Z20: 0 | AA20: 0 | AB20: 952 | AC20: 548 | AD20: 0 | AE20: 0 | AF20: 0 | AG20: 0
B21: 10423 | C21: 19 | D21: 1 | E21: 2 | F21: 0 | G21: 31 | H21: 0.3 | I21: 0.02 | J21: 0.07 | K21: 1 | L21: =$Y$4+SUMPRODUCT($Z$4:$AG$4,C21:J21) -> -1.2697474 | M21: =EXP(L21)/(1+EXP(L21)) -> 0.2193005 | N21: =IF(K21=1,M21,(1-M21)) -> 0.2193005 | O21: =LN(N21) -> -1.5173123 | P21: =IF(M21>0.4,1,0) -> 0 | Q21: =28.8539*LN((1-M21)/(M21))+487.123 -> 523.76016 | R21: =VLOOKUP(M21,$U$9:$W$16,3,TRUE) -> 6 | S21: =VLOOKUP(M21,$U$21:$W$37,3,TRUE) -> 13 | U21: 0 | V21: 0.0023893819 | W21: 1
B22: 10428 | C22: 19 | D22: 2 | E22: 0 | F22: 0 | G22: 26 | H22: 5.8 | I22: 0.59 | J22: 0.92 | K22: 1 | L22: =$Y$4+SUMPRODUCT($Z$4:$AG$4,C22:J22) -> -0.032456718 | M22: =EXP(L22)/(1+EXP(L22)) -> 0.49188653 | N22: =IF(K22=1,M22,(1-M22)) -> 0.49188653 | O22: =LN(N22) -> -0.70950721 | P22: =IF(M22>0.4,1,0) -> 1 | Q22: =28.8539*LN((1-M22)/(M22))+487.123 -> 488.0595 | R22: =VLOOKUP(M22,$U$9:$W$16,3,TRUE) -> 7 | S22: =VLOOKUP(M22,$U$21:$W$37,3,TRUE) -> 15 | U22: 0.0023893819 | V22: 0.0035840728 | W22: 2
B23: 10449 | C23: 56 | D23: 2 | E23: 27 | F23: 21 | G23: 125 | H23: 8.5 | I23: 2.9 | J23: 7.72 | K23: 0 | L23: =$Y$4+SUMPRODUCT($Z$4:$AG$4,C23:J23) -> -6.0681842 | M23: =EXP(L23)/(1+EXP(L23)) -> 0.0023100252 | N23: =IF(K23=1,M23,(1-M23)) -> 0.99768997 | O23: =LN(N23) -> -0.0023126974 | P23: =IF(M23>0.4,1,0) -> 0 | Q23: =28.8539*LN((1-M23)/(M23))+487.123 -> 662.21378 | R23: =VLOOKUP(M23,$U$9:$W$16,3,TRUE) -> 2 | S23: =VLOOKUP(M23,$U$21:$W$37,3,TRUE) -> 1 | U23: 0.0035840728 | V23: 0.0053761092 | W23: 3 | Z23: D | AA23: ND
B24: 10455 | C24: 21 | D24: 2 | E24: 1 | F24: 1 | G24: 40 | H24: 7.6 | I24: 1.52 | J24: 1.52 | K24: 1 | L24: =$Y$4+SUMPRODUCT($Z$4:$AG$4,C24:J24) -> 0.30359396 | M24: =EXP(L24)/(1+EXP(L24)) -> 0.57532085 | N24: =IF(K24=1,M24,(1-M24)) -> 0.57532085 | O24: =LN(N24) -> -0.55282739 | P24: =IF(M24>0.4,1,0) -> 1 | Q24: =28.8539*LN((1-M24)/(M24))+487.123 -> 478.36313 | R24: =VLOOKUP(M24,$U$9:$W$16,3,TRUE) -> 7 | S24: =VLOOKUP(M24,$U$21:$W$37,3,TRUE) -> 15 | U24: 0.0053761092 | V24: 0.0080641638 | W24: 4 | Y24: D | Z24: 403 | AA24: 145
B25: 10474 | C25: 25 | D25: 1 | E25: 8 | F25: 3 | G25: 37 | H25: 8.3 | I25: 0.95 | J25: 2.12 | K25: 0 | L25: =$Y$4+SUMPRODUCT($Z$4:$AG$4,C25:J25) -> -1.5641051 | M25: =EXP(L25)/(1+EXP(L25)) -> 0.17305838 | N25: =IF(K25=1,M25,(1-M25)) -> 0.82694162 | O25: =LN(N25) -> -0.19002117 | P25: =IF(M25>0.4,1,0) -> 0 | Q25: =28.8539*LN((1-M25)/(M25))+487.123 -> 532.25353 | R25: =VLOOKUP(M25,$U$9:$W$16,3,TRUE) -> 6 | S25: =VLOOKUP(M25,$U$21:$W$37,3,TRUE) -> 12 | U25: 0.0080641638 | V25: 0.012096246 | W25: 5 | Y25: ND | Z25: 222 | AA25: 730
B26: 10525 | C26: 47 | D26: 3 | E26: 8 | F26: 10 | G26: 43 | H26: 6.1 | I26: 0.36 | J26: 2.26 | K26: 0 | L26: =$Y$4+SUMPRODUCT($Z$4:$AG$4,C26:J26) -> -2.8680044 | M26: =EXP(L26)/(1+EXP(L26)) -> 0.053758072 | N26: =IF(K26=1,M26,(1-M26)) -> 0.94624193 | O26: =LN(N26) -> -0.055257005 | P26: =IF(M26>0.4,1,0) -> 0 | Q26: =28.8539*LN((1-M26)/(M26))+487.123 -> 569.87611 | R26: =VLOOKUP(M26,$U$9:$W$16,3,TRUE) -> 5 | S26: =VLOOKUP(M26,$U$21:$W$37,3,TRUE) -> 9 | U26: 0.012096246 | V26: 0.018144368 | W26: 6
B27: 10564 | C27: 40 | D27: 4 | E27: 17 | F27: 11 | G27: 103 | H27: 13.3 | I27: 10.41 | J27: 3.29 | K27: 1 | L27: =$Y$4+SUMPRODUCT($Z$4:$AG$4,C27:J27) -> 0.67843434 | M27: =EXP(L27)/(1+EXP(L27)) -> 0.66338917 | N27: =IF(K27=1,M27,(1-M27)) -> 0.66338917 | O27: =LN(N27) -> -0.41039348 | P27: =IF(M27>0.4,1,0) -> 1 | Q27: =28.8539*LN((1-M27)/(M27))+487.123 -> 467.54752 | R27: =VLOOKUP(M27,$U$9:$W$16,3,TRUE) -> 7 | S27: =VLOOKUP(M27,$U$21:$W$37,3,TRUE) -> 15 | U27: 0.018144368 | V27: 0.027216553 | W27: 7 | Z27: 0.75533333
B28: 10567 | C28: 41 | D28: 2 | E28: 16 | F28: 11 | G28: 56 | H28: 3.4 | I28: 0.9 | J28: 1.01 | K28: 0 | L28: =$Y$4+SUMPRODUCT($Z$4:$AG$4,C28:J28) -> -4.5692388 | M28: =EXP(L28)/(1+EXP(L28)) -> 0.010259498 | N28: =IF(K28=1,M28,(1-M28)) -> 0.9897405 | O28: =LN(N28) -> -0.01031249 | P28: =IF(M28>0.4,1,0) -> 0 | Q28: =28.8539*LN((1-M28)/(M28))+487.123 -> 618.96336 | R28: =VLOOKUP(M28,$U$9:$W$16,3,TRUE) -> 4 | S28: =VLOOKUP(M28,$U$21:$W$37,3,TRUE) -> 5 | U28: 0.027216553 | V28: 0.040824829 | W28: 8
B29: 10746 | C29: 23 | D29: 4 | E29: 0 | F29: 2 | G29: 118 | H29: 6.4 | I29: 0.29 | J29: 7.26 | K29: 0 | L29: =$Y$4+SUMPRODUCT($Z$4:$AG$4,C29:J29) -> -0.19346393 | M29: =EXP(L29)/(1+EXP(L29)) -> 0.45178431 | N29: =IF(K29=1,M29,(1-M29)) -> 0.54821569 | O29: =LN(N29) -> -0.60108647 | P29: =IF(M29>0.4,1,0) -> 1 | Q29: =28.8539*LN((1-M29)/(M29))+487.123 -> 492.70519 | R29: =VLOOKUP(M29,$U$9:$W$16,3,TRUE) -> 7 | S29: =VLOOKUP(M29,$U$21:$W$37,3,TRUE) -> 14 | U29: 0.040824829 | V29: 0.061237244 | W29: 9
B30: 10775 | C30: 45 | D30: 5 | E30: 1 | F30: 4 | G30: 58 | H30: 15.4 | I30: 2.37 | J30: 6.57 | K30: 1 | L30: =$Y$4+SUMPRODUCT($Z$4:$AG$4,C30:J30) -> 0.83790468 | M30: =EXP(L30)/(1+EXP(L30)) -> 0.69802373 | N30: =IF(K30=1,M30,(1-M30)) -> 0.69802373 | O30: =LN(N30) -> -0.35950217 | P30: =IF(M30>0.4,1,0) -> 1 | Q30: =28.8539*LN((1-M30)/(M30))+487.123 -> 462.94618 | R30: =VLOOKUP(M30,$U$9:$W$16,3,TRUE) -> 8 | S30: =VLOOKUP(M30,$U$21:$W$37,3,TRUE) -> 16 | U30: 0.061237244 | V30: 0.091855865 | W30: 10
B31: 10776 | C31: 37 | D31: 3 | E31: 15 | F31: 10 | G31: 65 | H31: 5 | I31: 1.3 | J31: 1.95 | K31: 0 | L31: =$Y$4+SUMPRODUCT($Z$4:$AG$4,C31:J31) -> -3.902928 | M31: =EXP(L31)/(1+EXP(L31)) -> 0.019783447 | N31: =IF(K31=1,M31,(1-M31)) -> 0.98021655 | O31: =LN(N31) -> -0.019981759 | P31: =IF(M31>0.4,1,0) -> 0 | Q31: =28.8539*LN((1-M31)/(M31))+487.123 -> 599.73769 | R31: =VLOOKUP(M31,$U$9:$W$16,3,TRUE) -> 4 | S31: =VLOOKUP(M31,$U$21:$W$37,3,TRUE) -> 7 | U31: 0.091855865 | V31: 0.1377838 | W31: 11
B32: 10797 | C32: 47 | D32: 2 | E32: 23 | F32: 14 | G32: 46 | H32: 11.7 | I32: 0.84 | J32: 4.54 | K32: 0 | L32: =$Y$4+SUMPRODUCT($Z$4:$AG$4,C32:J32) -> -5.4952658 | M32: =EXP(L32)/(1+EXP(L32)) -> 0.0040893733 | N32: =IF(K32=1,M32,(1-M32)) -> 0.99591063 | O32: =LN(N32) -> -0.0040977576 | P32: =IF(M32>0.4,1,0) -> 0 | Q32: =28.8539*LN((1-M32)/(M32))+487.123 -> 645.68285 | R32: =VLOOKUP(M32,$U$9:$W$16,3,TRUE) -> 3 | S32: =VLOOKUP(M32,$U$21:$W$37,3,TRUE) -> 3 | U32: 0.1377838 | V32: 0.2066757 | W32: 12
B33: 10798 | C33: 23 | D33: 4 | E33: 0 | F33: 2 | G33: 42 | H33: 6.7 | I33: 1.58 | J33: 1.23 | K33: 0 | L33: =$Y$4+SUMPRODUCT($Z$4:$AG$4,C33:J33) -> 0.27913173 | M33: =EXP(L33)/(1+EXP(L33)) -> 0.56933334 | N33: =IF(K33=1,M33,(1-M33)) -> 0.43066666 | O33: =LN(N33) -> -0.84242091 | P33: =IF(M33>0.4,1,0) -> 1 | Q33: =28.8539*LN((1-M33)/(M33))+487.123 -> 479.06896 | R33: =VLOOKUP(M33,$U$9:$W$16,3,TRUE) -> 7 | S33: =VLOOKUP(M33,$U$21:$W$37,3,TRUE) -> 15 | U33: 0.2066757 | V33: 0.31001355 | W33: 13 | Y33: LB | Z33: UB
B34: 10800 | C34: 18 | D34: 2 | E34: 0 | F34: 0 | G34: 19 | H34: 5.2 | I34: 0.32 | J34: 0.67 | K34: 1 | L34: =$Y$4+SUMPRODUCT($Z$4:$AG$4,C34:J34) -> -0.20637085 | M34: =EXP(L34)/(1+EXP(L34)) -> 0.44858962 | N34: =IF(K34=1,M34,(1-M34)) -> 0.44858962 | O34: =LN(N34) -> -0.8016468 | P34: =IF(M34>0.4,1,0) -> 1 | Q34: =28.8539*LN((1-M34)/(M34))+487.123 -> 493.0776 | R34: =VLOOKUP(M34,$U$9:$W$16,3,TRUE) -> 7 | S34: =VLOOKUP(M34,$U$21:$W$37,3,TRUE) -> 14 | U34: 0.31001355 | V34: 0.46502032 | W34: 14
B35: 10802 | C35: 19 | D35: 2 | E35: 0 | F35: 0 | G35: 21 | H35: 2 | I35: 0.28 | J35: 0.14 | K35: 1 | L35: =$Y$4+SUMPRODUCT($Z$4:$AG$4,C35:J35) -> -0.5786001 | M35: =EXP(L35)/(1+EXP(L35)) -> 0.35925477 | N35: =IF(K35=1,M35,(1-M35)) -> 0.35925477 | O35: =LN(N35) -> -1.0237235 | P35: =IF(M35>0.4,1,0) -> 0 | Q35: =28.8539*LN((1-M35)/(M35))+487.123 -> 503.81787 | R35: =VLOOKUP(M35,$U$9:$W$16,3,TRUE) -> 7 | S35: =VLOOKUP(M35,$U$21:$W$37,3,TRUE) -> 14 | U35: 0.46502032 | V35: 0.69753048 | W35: 15 | Y35: 0 | Z35: 15.120307
B36: 10805 | C36: 41 | D36: 1 | E36: 3 | F36: 12 | G36: 23 | H36: 10.6 | I36: 0.15 | J36: 2.29 | K36: 1 | L36: =$Y$4+SUMPRODUCT($Z$4:$AG$4,C36:J36) -> -1.2203484 | M36: =EXP(L36)/(1+EXP(L36)) -> 0.22787515 | N36: =IF(K36=1,M36,(1-M36)) -> 0.22787515 | O36: =LN(N36) -> -1.4789574 | P36: =IF(M36>0.4,1,0) -> 0 | Q36: =28.8539*LN((1-M36)/(M36))+487.123 -> 522.33481 | R36: =VLOOKUP(M36,$U$9:$W$16,3,TRUE) -> 6 | S36: =VLOOKUP(M36,$U$21:$W$37,3,TRUE) -> 13 | U36: 0.69753048 | V36: 0.92428182 | W36: 16 | Y36: 15.120307 | Z36: 32.075015
B37: 10824 | C37: 42 | D37: 2 | E37: 3 | F37: 12 | G37: 76 | H37: 5.2 | I37: 0.72 | J37: 3.23 | K37: 1 | L37: =$Y$4+SUMPRODUCT($Z$4:$AG$4,C37:J37) -> -1.5279697 | M37: =EXP(L37)/(1+EXP(L37)) -> 0.17829093 | N37: =IF(K37=1,M37,(1-M37)) -> 0.17829093 | O37: =LN(N37) -> -1.7243386 | P37: =IF(M37>0.4,1,0) -> 0 | Q37: =28.8539*LN((1-M37)/(M37))+487.123 -> 531.21089 | R37: =VLOOKUP(M37,$U$9:$W$16,3,TRUE) -> 6 | S37: =VLOOKUP(M37,$U$21:$W$37,3,TRUE) -> 12 | U37: 0.92428182 | V37: 1 | W37: 17 | Y37: 32.075015 | Z37: 96.225045
B38: 10839 | C38: 29 | D38: 4 | E38: 2 | F38: 3 | G38: 45 | H38: 3 | I38: 0.67 | J38: 0.68 | K38: 0 | L38: =$Y$4+SUMPRODUCT($Z$4:$AG$4,C38:J38) -> -1.148397 | M38: =EXP(L38)/(1+EXP(L38)) -> 0.240782 | N38: =IF(K38=1,M38,(1-M38)) -> 0.759218 | O38: =LN(N38) -> -0.27546632 | P38: =IF(M38>0.4,1,0) -> 0 | Q38: =28.8539*LN((1-M38)/(M38))+487.123 -> 520.25873 | R38: =VLOOKUP(M38,$U$9:$W$16,3,TRUE) -> 6 | S38: =VLOOKUP(M38,$U$21:$W$37,3,TRUE) -> 13 | Y38: 96.225045 | Z38: 288.67513
B39: 10870 | C39: 24 | D39: 4 | E39: 0 | F39: 2 | G39: 41 | H39: 8.4 | I39: 0.79 | J39: 2.66 | K39: 0 | L39: =$Y$4+SUMPRODUCT($Z$4:$AG$4,C39:J39) -> 0.088381182 | M39: =EXP(L39)/(1+EXP(L39)) -> 0.52208092 | N39: =IF(K39=1,M39,(1-M39)) -> 0.47791908 | O39: =LN(N39) -> -0.73831386 | P39: =IF(M39>0.4,1,0) -> 1 | Q39: =28.8539*LN((1-M39)/(M39))+487.123 -> 484.57286 | R39: =VLOOKUP(M39,$U$9:$W$16,3,TRUE) -> 7 | S39: =VLOOKUP(M39,$U$21:$W$37,3,TRUE) -> 15 | Y39: 288.67513 | Z39: 866.0254
B40: 10884 | C40: 45 | D40: 5 | E40: 9 | F40: 11 | G40: 48 | H40: 10.2 | I40: 3.53 | J40: 1.37 | K40: 0 | L40: =$Y$4+SUMPRODUCT($Z$4:$AG$4,C40:J40) -> -1.3015596 | M40: =EXP(L40)/(1+EXP(L40)) -> 0.21390266 | N40: =IF(K40=1,M40,(1-M40)) -> 0.78609734 | O40: =LN(N40) -> -0.24067465 | P40: =IF(M40>0.4,1,0) -> 0 | Q40: =28.8539*LN((1-M40)/(M40))+487.123 -> 524.67807 | R40: =VLOOKUP(M40,$U$9:$W$16,3,TRUE) -> 6 | S40: =VLOOKUP(M40,$U$21:$W$37,3,TRUE) -> 13 | Y40: 866.0254 | Z40: 2598.0762
B41: 10887 | C41: 39 | D41: 4 | E41: 8 | F41: 9 | G41: 259 | H41: 7.2 | I41: 1.55 | J41: 17.1 | K41: 0 | L41: =$Y$4+SUMPRODUCT($Z$4:$AG$4,C41:J41) -> -1.6218858 | M41: =EXP(L41)/(1+EXP(L41)) -> 0.16494496 | N41: =IF(K41=1,M41,(1-M41)) -> 0.83505504 | O41: =LN(N41) -> -0.18025764 | P41: =IF(M41>0.4,1,0) -> 0 | Q41: =28.8539*LN((1-M41)/(M41))+487.123 -> 533.92073 | R41: =VLOOKUP(M41,$U$9:$W$16,3,TRUE) -> 6 | S41: =VLOOKUP(M41,$U$21:$W$37,3,TRUE) -> 12 | Y41: 2598.0762 | Z41: 6708.2039
...

Sheet ROC_GINI_AUC_KS
B2: default | C2: Score | E2: Good | F2: Bad | G2: Total | W2: ROCAUC | X2: =SUM(X8:X61) -> 0.84190218 | Z2: GINI | AB2: CAPAUC | AC2: =SUM(AD8:AD61) -> 0.71699392 | AE2: Accuracy Ratio
B3: =MODEL!K4 -> 0 | C3: =MODEL!Q4 -> 471.30233 | E3: =COUNTIFS($B$3:$B$1502,0) -> 952 | F3: =G3-E3 -> 548 | G3: =COUNT(B3:B1502) -> 1500 | L3: Check all the Graphs at the bottom | Z3: =2*X2-1 -> 0.68380436 | AB3: A_random | AC3: 0.5 | AE3: =(AC2-AC3)/(AC4-AC3) -> 0.68380436
B4: =MODEL!K5 -> 0 | C4: =MODEL!Q5 -> 663.50147 | E4: =E3/G3 -> 0.63466667 | F4: =F3/G3 -> 0.36533333 | AB4: A_perfect | AC4: =1-(0.5*1*F4) -> 0.81733333
B5: =MODEL!K6 -> 0 | C5: =MODEL!Q6 -> 637.24241 | L5: Graph: Bottom | P5: Graph: Bottom
B6: =MODEL!K7 -> 0 | C6: =MODEL!Q7 -> 464.82262 | E6: Total Bins | F6: =COUNT(E8:E61) -> 54 | H6: Cumulative % | L6: Cumulative % | P6: Marginal | AA6: CAP Curve
B7: =MODEL!K8 -> 1 | C7: =MODEL!Q8 -> 451.47042 | E7: Bucket | F7: Score | H7: Comm.Goods | I7: Comm.Bads | J7: Total | L7: Good | M7: Bad | N7: Total | P7: Good | Q7: Bad | R7: Total | T7: KS | V7: Width | W7: Sum of Parallel Sides | X7: AUC | AA7: Comm % Accounts | AB7: Comm % Bad | AC7: Dx | AD7: Area Under Curve
B8: =MODEL!K9 -> 1 | C8: =MODEL!Q9 -> 490.10023 | E8: 1 | F8: 60 | H8: =COUNTIFS($C$3:$C$1502,"<="&F8,$B$3:$B$1502,0) -> 0 | I8: =COUNTIFS($C$3:$C$1502,"<="&F8,$B$3:$B$1502,1) -> 1 | J8: =SUM(H8:I8) -> 1 | L8: =H8/$E$3 -> 0 | M8: =I8/$F$3 -> 0.0018248175 | N8: =J8/$G$3 -> 0.00066666667 | P8: =H8/$E$3 -> 0 | Q8: =M8/$F$3 -> 3.329959e-06 | R8: =N8/$F$3 -> 1.216545e-06 | T8: =M8-L8 -> 0.0018248175 | V8: =P8 -> 0 | W8: =M8 -> 0.0018248175 | X8: =0.5*V8*W8 -> 0 | AA8: =N8 -> 0.00066666667 | AB8: =M8 -> 0.0018248175 | AC8: =AA8 -> 0.00066666667 | AD8: =AC8*0.5*AB8 -> 6.0827251e-07
B9: =MODEL!K10 -> 1 | C9: =MODEL!Q10 -> 486.32491 | E9: 2 | F9: =F8+15 -> 75 | H9: =COUNTIFS($C$3:$C$1502,"<="&F9,$B$3:$B$1502,0) -> 0 | I9: =COUNTIFS($C$3:$C$1502,"<="&F9,$B$3:$B$1502,1) -> 1 | J9: =SUM(H9:I9) -> 1 | L9: =H9/$E$3 -> 0 | M9: =I9/$F$3 -> 0.0018248175 | N9: =J9/$G$3 -> 0.00066666667 | P9: =(H9-H8)/$E$3 -> 0 | Q9: =(I9-I8)/$E$3 -> 0 | R9: =(J9-J8)/$E$3 -> 0 | T9: =M9-L9 -> 0.0018248175 | V9: =P9 -> 0 | W9: =M9+M8 -> 0.003649635 | X9: =0.5*V9*W9 -> 0 | AA9: =N9 -> 0.00066666667 | AB9: =M9 -> 0.0018248175 | AC9: =AA9-AA8 -> 0 | AD9: =0.5*AC9*(AB9+AB8) -> 0
B10: =MODEL!K11 -> 0 | C10: =MODEL!Q11 -> 485.51028 | E10: 3 | F10: =F9+15 -> 90 | H10: =COUNTIFS($C$3:$C$1502,"<="&F10,$B$3:$B$1502,0) -> 0 | I10: =COUNTIFS($C$3:$C$1502,"<="&F10,$B$3:$B$1502,1) -> 1 | J10: =SUM(H10:I10) -> 1 | L10: =H10/$E$3 -> 0 | M10: =I10/$F$3 -> 0.0018248175 | N10: =J10/$G$3 -> 0.00066666667 | P10: =(H10-H9)/$E$3 -> 0 | Q10: =(I10-I9)/$E$3 -> 0 | R10: =(J10-J9)/$E$3 -> 0 | T10: =M10-L10 -> 0.0018248175 | V10: =P10 -> 0 | W10: =M10+M9 -> 0.003649635 | X10: =0.5*V10*W10 -> 0 | AA10: =N10 -> 0.00066666667 | AB10: =M10 -> 0.0018248175 | AC10: =AA10-AA9 -> 0 | AD10: =0.5*AC10*(AB10+AB9) -> 0
B11: =MODEL!K12 -> 0 | C11: =MODEL!Q12 -> 681.92939 | E11: 4 | F11: =F10+15 -> 105 | H11: =COUNTIFS($C$3:$C$1502,"<="&F11,$B$3:$B$1502,0) -> 0 | I11: =COUNTIFS($C$3:$C$1502,"<="&F11,$B$3:$B$1502,1) -> 1 | J11: =SUM(H11:I11) -> 1 | L11: =H11/$E$3 -> 0 | M11: =I11/$F$3 -> 0.0018248175 | N11: =J11/$G$3 -> 0.00066666667 | P11: =(H11-H10)/$E$3 -> 0 | Q11: =(I11-I10)/$E$3 -> 0 | R11: =(J11-J10)/$E$3 -> 0 | T11: =M11-L11 -> 0.0018248175 | V11: =P11 -> 0 | W11: =M11+M10 -> 0.003649635 | X11: =0.5*V11*W11 -> 0 | AA11: =N11 -> 0.00066666667 | AB11: =M11 -> 0.0018248175 | AC11: =AA11-AA10 -> 0 | AD11: =0.5*AC11*(AB11+AB10) -> 0
B12: =MODEL!K13 -> 0 | C12: =MODEL!Q13 -> 500.3948 | E12: 5 | F12: =F11+15 -> 120 | H12: =COUNTIFS($C$3:$C$1502,"<="&F12,$B$3:$B$1502,0) -> 0 | I12: =COUNTIFS($C$3:$C$1502,"<="&F12,$B$3:$B$1502,1) -> 1 | J12: =SUM(H12:I12) -> 1 | L12: =H12/$E$3 -> 0 | M12: =I12/$F$3 -> 0.0018248175 | N12: =J12/$G$3 -> 0.00066666667 | P12: =(H12-H11)/$E$3 -> 0 | Q12: =(I12-I11)/$E$3 -> 0 | R12: =(J12-J11)/$E$3 -> 0 | T12: =M12-L12 -> 0.0018248175 | V12: =P12 -> 0 | W12: =M12+M11 -> 0.003649635 | X12: =0.5*V12*W12 -> 0 | AA12: =N12 -> 0.00066666667 | AB12: =M12 -> 0.0018248175 | AC12: =AA12-AA11 -> 0 | AD12: =0.5*AC12*(AB12+AB11) -> 0
B13: =MODEL!K14 -> 0 | C13: =MODEL!Q14 -> 616.83431 | E13: 6 | F13: =F12+15 -> 135 | H13: =COUNTIFS($C$3:$C$1502,"<="&F13,$B$3:$B$1502,0) -> 0 | I13: =COUNTIFS($C$3:$C$1502,"<="&F13,$B$3:$B$1502,1) -> 1 | J13: =SUM(H13:I13) -> 1 | L13: =H13/$E$3 -> 0 | M13: =I13/$F$3 -> 0.0018248175 | N13: =J13/$G$3 -> 0.00066666667 | P13: =(H13-H12)/$E$3 -> 0 | Q13: =(I13-I12)/$E$3 -> 0 | R13: =(J13-J12)/$E$3 -> 0 | T13: =M13-L13 -> 0.0018248175 | V13: =P13 -> 0 | W13: =M13+M12 -> 0.003649635 | X13: =0.5*V13*W13 -> 0 | AA13: =N13 -> 0.00066666667 | AB13: =M13 -> 0.0018248175 | AC13: =AA13-AA12 -> 0 | AD13: =0.5*AC13*(AB13+AB12) -> 0
B14: =MODEL!K15 -> 1 | C14: =MODEL!Q15 -> 487.85006 | E14: 7 | F14: =F13+15 -> 150 | H14: =COUNTIFS($C$3:$C$1502,"<="&F14,$B$3:$B$1502,0) -> 0 | I14: =COUNTIFS($C$3:$C$1502,"<="&F14,$B$3:$B$1502,1) -> 1 | J14: =SUM(H14:I14) -> 1 | L14: =H14/$E$3 -> 0 | M14: =I14/$F$3 -> 0.0018248175 | N14: =J14/$G$3 -> 0.00066666667 | P14: =(H14-H13)/$E$3 -> 0 | Q14: =(I14-I13)/$E$3 -> 0 | R14: =(J14-J13)/$E$3 -> 0 | T14: =M14-L14 -> 0.0018248175 | V14: =P14 -> 0 | W14: =M14+M13 -> 0.003649635 | X14: =0.5*V14*W14 -> 0 | AA14: =N14 -> 0.00066666667 | AB14: =M14 -> 0.0018248175 | AC14: =AA14-AA13 -> 0 | AD14: =0.5*AC14*(AB14+AB13) -> 0
B15: =MODEL!K16 -> 0 | C15: =MODEL!Q16 -> 386.27557 | E15: 8 | F15: =F14+15 -> 165 | H15: =COUNTIFS($C$3:$C$1502,"<="&F15,$B$3:$B$1502,0) -> 0 | I15: =COUNTIFS($C$3:$C$1502,"<="&F15,$B$3:$B$1502,1) -> 1 | J15: =SUM(H15:I15) -> 1 | L15: =H15/$E$3 -> 0 | M15: =I15/$F$3 -> 0.0018248175 | N15: =J15/$G$3 -> 0.00066666667 | P15: =(H15-H14)/$E$3 -> 0 | Q15: =(I15-I14)/$E$3 -> 0 | R15: =(J15-J14)/$E$3 -> 0 | T15: =M15-L15 -> 0.0018248175 | V15: =P15 -> 0 | W15: =M15+M14 -> 0.003649635 | X15: =0.5*V15*W15 -> 0 | AA15: =N15 -> 0.00066666667 | AB15: =M15 -> 0.0018248175 | AC15: =AA15-AA14 -> 0 | AD15: =0.5*AC15*(AB15+AB14) -> 0
B16: =MODEL!K17 -> 0 | C16: =MODEL!Q17 -> 498.38562 | E16: 9 | F16: =F15+15 -> 180 | H16: =COUNTIFS($C$3:$C$1502,"<="&F16,$B$3:$B$1502,0) -> 0 | I16: =COUNTIFS($C$3:$C$1502,"<="&F16,$B$3:$B$1502,1) -> 1 | J16: =SUM(H16:I16) -> 1 | L16: =H16/$E$3 -> 0 | M16: =I16/$F$3 -> 0.0018248175 | N16: =J16/$G$3 -> 0.00066666667 | P16: =(H16-H15)/$E$3 -> 0 | Q16: =(I16-I15)/$E$3 -> 0 | R16: =(J16-J15)/$E$3 -> 0 | T16: =M16-L16 -> 0.0018248175 | V16: =P16 -> 0 | W16: =M16+M15 -> 0.003649635 | X16: =0.5*V16*W16 -> 0 | AA16: =N16 -> 0.00066666667 | AB16: =M16 -> 0.0018248175 | AC16: =AA16-AA15 -> 0 | AD16: =0.5*AC16*(AB16+AB15) -> 0
B17: =MODEL!K18 -> 0 | C17: =MODEL!Q18 -> 531.64499 | E17: 10 | F17: =F16+15 -> 195 | H17: =COUNTIFS($C$3:$C$1502,"<="&F17,$B$3:$B$1502,0) -> 0 | I17: =COUNTIFS($C$3:$C$1502,"<="&F17,$B$3:$B$1502,1) -> 1 | J17: =SUM(H17:I17) -> 1 | L17: =H17/$E$3 -> 0 | M17: =I17/$F$3 -> 0.0018248175 | N17: =J17/$G$3 -> 0.00066666667 | P17: =(H17-H16)/$E$3 -> 0 | Q17: =(I17-I16)/$E$3 -> 0 | R17: =(J17-J16)/$E$3 -> 0 | T17: =M17-L17 -> 0.0018248175 | V17: =P17 -> 0 | W17: =M17+M16 -> 0.003649635 | X17: =0.5*V17*W17 -> 0 | AA17: =N17 -> 0.00066666667 | AB17: =M17 -> 0.0018248175 | AC17: =AA17-AA16 -> 0 | AD17: =0.5*AC17*(AB17+AB16) -> 0
B18: =MODEL!K19 -> 1 | C18: =MODEL!Q19 -> 480.09089 | E18: 11 | F18: =F17+15 -> 210 | H18: =COUNTIFS($C$3:$C$1502,"<="&F18,$B$3:$B$1502,0) -> 0 | I18: =COUNTIFS($C$3:$C$1502,"<="&F18,$B$3:$B$1502,1) -> 1 | J18: =SUM(H18:I18) -> 1 | L18: =H18/$E$3 -> 0 | M18: =I18/$F$3 -> 0.0018248175 | N18: =J18/$G$3 -> 0.00066666667 | P18: =(H18-H17)/$E$3 -> 0 | Q18: =(I18-I17)/$E$3 -> 0 | R18: =(J18-J17)/$E$3 -> 0 | T18: =M18-L18 -> 0.0018248175 | V18: =P18 -> 0 | W18: =M18+M17 -> 0.003649635 | X18: =0.5*V18*W18 -> 0 | AA18: =N18 -> 0.00066666667 | AB18: =M18 -> 0.0018248175 | AC18: =AA18-AA17 -> 0 | AD18: =0.5*AC18*(AB18+AB17) -> 0
B19: =MODEL!K20 -> 1 | C19: =MODEL!Q20 -> 437.32622 | E19: 12 | F19: =F18+15 -> 225 | H19: =COUNTIFS($C$3:$C$1502,"<="&F19,$B$3:$B$1502,0) -> 0 | I19: =COUNTIFS($C$3:$C$1502,"<="&F19,$B$3:$B$1502,1) -> 1 | J19: =SUM(H19:I19) -> 1 | L19: =H19/$E$3 -> 0 | M19: =I19/$F$3 -> 0.0018248175 | N19: =J19/$G$3 -> 0.00066666667 | P19: =(H19-H18)/$E$3 -> 0 | Q19: =(I19-I18)/$E$3 -> 0 | R19: =(J19-J18)/$E$3 -> 0 | T19: =M19-L19 -> 0.0018248175 | V19: =P19 -> 0 | W19: =M19+M18 -> 0.003649635 | X19: =0.5*V19*W19 -> 0 | AA19: =N19 -> 0.00066666667 | AB19: =M19 -> 0.0018248175 | AC19: =AA19-AA18 -> 0 | AD19: =0.5*AC19*(AB19+AB18) -> 0
B20: =MODEL!K21 -> 1 | C20: =MODEL!Q21 -> 523.76016 | E20: 13 | F20: =F19+15 -> 240 | H20: =COUNTIFS($C$3:$C$1502,"<="&F20,$B$3:$B$1502,0) -> 0 | I20: =COUNTIFS($C$3:$C$1502,"<="&F20,$B$3:$B$1502,1) -> 1 | J20: =SUM(H20:I20) -> 1 | L20: =H20/$E$3 -> 0 | M20: =I20/$F$3 -> 0.0018248175 | N20: =J20/$G$3 -> 0.00066666667 | P20: =(H20-H19)/$E$3 -> 0 | Q20: =(I20-I19)/$E$3 -> 0 | R20: =(J20-J19)/$E$3 -> 0 | T20: =M20-L20 -> 0.0018248175 | V20: =P20 -> 0 | W20: =M20+M19 -> 0.003649635 | X20: =0.5*V20*W20 -> 0 | AA20: =N20 -> 0.00066666667 | AB20: =M20 -> 0.0018248175 | AC20: =AA20-AA19 -> 0 | AD20: =0.5*AC20*(AB20+AB19) -> 0
... B61: =MODEL!K62 -> 1 | C61: =MODEL!Q62 -> 556.0365 | E61: 54 | F61: =F60+15 -> 855 | H61: =COUNTIFS($C$3:$C$1502,"<="&F61,$B$3:$B$1502,0) -> 952 | I61: =COUNTIFS($C$3:$C$1502,"<="&F61,$B$3:$B$1502,1) -> 548 | J61: =SUM(H61:I61) -> 1500 | L61: =H61/$E$3 -> 1 | M61: =I61/$F$3 -> 1 | N61: =J61/$G$3 -> 1 | P61: =(H61-H60)/$E$3 -> 0.0010504202 | Q61: =(I61-I60)/$E$3 -> 0 | R61: =(J61-J60)/$E$3 -> 0.0010504202 | T61: =M61-L61 -> 0 | V61: =P61 -> 0.0010504202 | W61: =M61+M60 -> 2 | X61: =0.5*V61*W61 -> 0.0010504202 | AA61: =N61 -> 1 | AB61: =M61 -> 1 | AC61: =AA61-AA60 -> 0.00066666667 | AD61: =0.5*AC61*(AB61+AB60) -> 0.00066666667
B62: =MODEL!K63 -> 0 | C62: =MODEL!Q63 -> 503.46725
B63: =MODEL!K64 -> 1 | C63: =MODEL!Q64 -> 480.23476
B64: =MODEL!K65 -> 1 | C64: =MODEL!Q65 -> 401.40283
B65: =MODEL!K66 -> 0 | C65: =MODEL!Q66 -> 550.68887
B66: =MODEL!K67 -> 1 | C66: =MODEL!Q67 -> 507.4288
B67: =MODEL!K68 -> 0 | C67: =MODEL!Q68 -> 476.12731
B68: =MODEL!K69 -> 0 | C68: =MODEL!Q69 -> 553.82103
B69: =MODEL!K70 -> 0 | C69: =MODEL!Q70 -> 541.84098
B70: =MODEL!K71 -> 0 | C70: =MODEL!Q71 -> 532.01764
B71: =MODEL!K72 -> 1 | C71: =MODEL!Q72 -> 530.1466
B72: =MODEL!K73 -> 0 | C72: =MODEL!Q73 -> 468.51746
B73: =MODEL!K74 -> 1 | C73: =MODEL!Q74 -> 486.70625
... B78: =MODEL!K79 -> 0 | C78: =MODEL!Q79 -> 548.56701
B79: =MODEL!K80 -> 1 | C79: =MODEL!Q80 -> 501.02916 | N79: Maximum Distance 30th Bucket | U79: 30th Bucket | AB79: 30th Bucket
B80: =MODEL!K81 -> 1 | C80: =MODEL!Q81 -> 498.79327
B81: =MODEL!K82 -> 0 | C81: =MODEL!Q82 -> 526.59397
B82: =MODEL!K83 -> 1 | C82: =MODEL!Q83 -> 495.91683
B83: =MODEL!K84 -> 0 | C83: =MODEL!Q84 -> 584.33358
B84: =MODEL!K85 -> 0 | C84: =MODEL!Q85 -> 574.92193
B85: =MODEL!K86 -> 0 | C85: =MODEL!Q86 -> 579.98136
...

Sheet Score Equation Logic
C2: Logistic Regression - linking PD to Credit Score
H3: =(H4-I7)/10 -> 25
C4: In Credit Scoring Applications, score is linearly linked to Log (Odds) | H4: =I8-I7 -> 550
C5: Assume Score = Factor x ln (Odds) + Offset
C6: First we decide a base score which corresponds to a base Odds | G6: Assuming
C7: Let's say a Score 600 refers to an Odds ratio 50 : 1 | G7: 1 | H7: MIN | I7: 300
G8: 2 | H8: MAX | I8: 850
B9: Then | C9: 600 = Factor x ln(50) + Offset
B11: Now, | C11: assume score increases by 20 points when the odds double | H11: Equation | I11: Offset + (Offset)*(Log Odds)
B12: Then | C12: 620 = Factor x ln(100) + Offset | H12: where | I12: Logs odds = Ln ((1-PD)/PD
C14: Subtracting , 20 = Factor x ln(2)
B15: Factor = | C15: 28.853901
B16: Offset = | C16: 487.12288
C18: Score = 28.8539 x ln ((1-PD)/PD) + 487.123
B21: If | C21: PD | D21: 0.005
B22: Then | C22: Score | D22: 639.85537

Sheet Score Equation Example
B2: Prob | C2: Odds | D2: Log Odds | E2: Score
B3: 1e-05 | C3: =B3/(1-B3) -> 1.00001e-05 | D3: =LN(C3) -> -11.512915 | E3: =$H$4+($H$3*D3) -> 262.17711 | G3: Factor | H3: =(H4-I7)/10 -> 25 | I3: (Mid - Low)/10
B4: 0.04 | C4: =B4/(1-B4) -> 0.041666667 | D4: =LN(C4) -> -3.1780538 | E4: =$H$4+($H$3*D4) -> 470.54865 | G4: Offset | H4: =I8-I7 -> 550 | I4: Based on Mid Value of score band
B5: 0.08 | C5: =B5/(1-B5) -> 0.086956522 | D5: =LN(C5) -> -2.442347 | E5: =$H$4+($H$3*D5) -> 488.94132
B6: 0.12 | C6: =B6/(1-B6) -> 0.13636364 | D6: =LN(C6) -> -1.9924302 | E6: =$H$4+($H$3*D6) -> 500.18925 | G6: Assuming
B7: 0.16 | C7: =B7/(1-B7) -> 0.19047619 | D7: =LN(C7) -> -1.6582281 | E7: =$H$4+($H$3*D7) -> 508.5443 | G7: 1 | H7: MIN | I7: 300
B8: 0.2 | C8: =B8/(1-B8) -> 0.25 | D8: =LN(C8) -> -1.3862944 | E8: =$H$4+($H$3*D8) -> 515.34264 | G8: 2 | H8: MAX | I8: 850
B9: 0.24 | C9: =B9/(1-B9) -> 0.31578947 | D9: =LN(C9) -> -1.1526795 | E9: =$H$4+($H$3*D9) -> 521.18301
B10: 0.28 | C10: =B10/(1-B10) -> 0.38888889 | D10: =LN(C10) -> -0.94446161 | E10: =$H$4+($H$3*D10) -> 526.38846
B11: 0.32 | C11: =B11/(1-B11) -> 0.47058824 | D11: =LN(C11) -> -0.7537718 | E11: =$H$4+($H$3*D11) -> 531.1557 | H11: Equation | I11: Offset + (Offset)*(Log Odds)
B12: 0.36 | C12: =B12/(1-B12) -> 0.5625 | D12: =LN(C12) -> -0.57536414 | E12: =$H$4+($H$3*D12) -> 535.6159 | H12: where | I12: Logs odds = Ln ((1-PD)/PD
B13: 0.4 | C13: =B13/(1-B13) -> 0.66666667 | D13: =LN(C13) -> -0.40546511 | E13: =$H$4+($H$3*D13) -> 539.86337
B14: 0.44 | C14: =B14/(1-B14) -> 0.78571429 | D14: =LN(C14) -> -0.24116206 | E14: =$H$4+($H$3*D14) -> 543.97095
B15: 0.48 | C15: =B15/(1-B15) -> 0.92307692 | D15: =LN(C15) -> -0.080042708 | E15: =$H$4+($H$3*D15) -> 547.99893
B16: 0.52 | C16: =B16/(1-B16) -> 1.0833333 | D16: =LN(C16) -> 0.080042708 | E16: =$H$4+($H$3*D16) -> 552.00107
B17: 0.56 | C17: =B17/(1-B17) -> 1.2727273 | D17: =LN(C17) -> 0.24116206 | E17: =$H$4+($H$3*D17) -> 556.02905
B18: 0.6 | C18: =B18/(1-B18) -> 1.5 | D18: =LN(C18) -> 0.40546511 | E18: =$H$4+($H$3*D18) -> 560.13663
B19: 0.64 | C19: =B19/(1-B19) -> 1.7777778 | D19: =LN(C19) -> 0.57536414 | E19: =$H$4+($H$3*D19) -> 564.3841
B20: 0.68 | C20: =B20/(1-B20) -> 2.125 | D20: =LN(C20) -> 0.7537718 | E20: =$H$4+($H$3*D20) -> 568.8443
B21: 0.72 | C21: =B21/(1-B21) -> 2.5714286 | D21: =LN(C21) -> 0.94446161 | E21: =$H$4+($H$3*D21) -> 573.61154
B22: 0.76 | C22: =B22/(1-B22) -> 3.1666667 | D22: =LN(C22) -> 1.1526795 | E22: =$H$4+($H$3*D22) -> 578.81699
B23: 0.8 | C23: =B23/(1-B23) -> 4 | D23: =LN(C23) -> 1.3862944 | E23: =$H$4+($H$3*D23) -> 584.65736
B24: 0.84 | C24: =B24/(1-B24) -> 5.25 | D24: =LN(C24) -> 1.6582281 | E24: =$H$4+($H$3*D24) -> 591.4557
... B28: 0.99999 | C28: =B28/(1-B28) -> 99999 | D28: =LN(C28) -> 11.512915 | E28: =$H$4+($H$3*D28) -> 837.82289
